Workbook
Name Rentabilidad: 'Base de Datos'!$AS:$AS
Name Publicar: 'Base de Datos'!$AG$1
Name Precio: 'Base de Datos'!$F:$F

Sheet Info general barrios
A1: Barrio | B1: Amenidades | C1: Links amenidades | D1: Fotos amenidades | E1: Precio más bajo | F1: Precio promedio | G1: Habitaciones promedio | H1: Baños promedio | I1: Área promedio | J1: Estrato
A2: Las Granjas | B2: Gimnasio Comfamiliar CAPF, Iglesia San Judas Tadeo, Colegio Maria Cristina Arango, Aeropuerto Benito Salas , Centro comercial San Pedro Plaza , Centro comercial San Juan Plaza , Centro de salud Carmen Emilia Ospina , | C2: https://gimnasioscomfamiliar.com/sede-cambulos/ , https://diocesisdeneiva.org/directorio/parroquias/San-Judas-Tadeo-Neiva , https://www.iemariacristinaarango.edu.co/, https://www.aerocivil.gov.co/aeropuertos/Pages/Benito-Salas.aspx , https://sanpedroplazacomercial.com.co/ , https://sanjuanplazacc.com/ , https://esecarmenemiliaospina.gov.co/ | D2: https://i.imgur.com/uvF7ybU.jpeg , https://i.imgur.com/4UFnHhg.jpeg , https://i.imgur.com/dpY74R2.jpeg , https://imgur.com/yBDIUKl.jpeg , https://i.imgur.com/0McV52E.jpeg , https://i.imgur.com/ZfvQIV4.jpeg , | E2: =IFERROR(MINIFS('Inventario barrios'!F:F,'Inventario barrios'!D:D,TRIM(A2),'Inventario barrios'!F:F,">0"),0) -> 130000000 | F2: =IFERROR(AVERAGEIFS('Inventario barrios'!F:F,'Inventario barrios'!D:D,TRIM(A2),'Inventario barrios'!F:F,">0"),0) -> 5.9255102e+08 | G2: =IFERROR(AVERAGEIFS('Inventario barrios'!J:J,'Inventario barrios'!D:D,TRIM(A2),'Inventario barrios'!J:J,">0"),0) -> 0 | H2: =IFERROR(AVERAGEIFS('Inventario barrios'!K:K,'Inventario barrios'!D:D,TRIM(A2),'Inventario barrios'!K:K,">0"),0) -> 0 | I2: =IFERROR(AVERAGEIFS('Inventario barrios'!N:N,'Inventario barrios'!D:D,TRIM(A2),'Inventario barrios'!N:N,">0"),0) -> 3.1458333 | J2: 2
A3: Los Cámbulos II | B3: Gimnasio Comfamiliar CAPF, Iglesia San Judas Tadeo, Aeropuerto Benito Salas , Centro comercial San Pedro Plaza , Centro comercial San Juan Plaza , Centro de salud Carmen Emilia Ospina , | C3: https://gimnasioscomfamiliar.com/sede-cambulos/ , https://diocesisdeneiva.org/directorio/parroquias/San-Judas-Tadeo-Neiva , https://www.aerocivil.gov.co/aeropuertos/Pages/Benito-Salas.aspx , https://sanpedroplazacomercial.com.co/ , https://sanjuanplazacc.com/ , https://esecarmenemiliaospina.gov.co/ , | D3: https://i.imgur.com/uvF7ybU.jpeg , https://i.imgur.com/4UFnHhg.jpeg , https://imgur.com/yBDIUKl.jpeg, https://i.imgur.com/0McV52E.jpeg , https://i.imgur.com/ZfvQIV4.jpeg , https://imgur.com/US4kxwg.jpeg | E3: =IFERROR(MINIFS('Inventario barrios'!F:F,'Inventario barrios'!D:D,TRIM(A3),'Inventario barrios'!F:F,">0"),0) -> 153000000 | F3: =IFERROR(AVERAGEIFS('Inventario barrios'!F:F,'Inventario barrios'!D:D,TRIM(A3),'Inventario barrios'!F:F,">0"),0) -> 309720000 | G3: =IFERROR(AVERAGEIFS('Inventario barrios'!J:J,'Inventario barrios'!D:D,TRIM(A3),'Inventario barrios'!J:J,">0"),0) -> 0 | H3: =IFERROR(AVERAGEIFS('Inventario barrios'!K:K,'Inventario barrios'!D:D,TRIM(A3),'Inventario barrios'!K:K,">0"),0) -> 0 | I3: =IFERROR(AVERAGEIFS('Inventario barrios'!N:N,'Inventario barrios'!D:D,TRIM(A3),'Inventario barrios'!N:N,">0"),0) -> 2.76 | J3: 3
A4: Los Molinos | B4: Gimnasio Comfamiliar CAPF, Iglesia San Judas Tadeo, Aeropuerto Benito Salas , Centro comercial San Pedro Plaza , Centro comercial San Juan Plaza , Centro de salud Carmen Emilia Ospina , | C4: https://gimnasioscomfamiliar.com/sede-cambulos/ , https://diocesisdeneiva.org/directorio/parroquias/San-Judas-Tadeo-Neiva , https://www.aerocivil.gov.co/aeropuertos/Pages/Benito-Salas.aspx , https://sanpedroplazacomercial.com.co/ , https://sanjuanplazacc.com/ , https://esecarmenemiliaospina.gov.co/ , | D4: https://i.imgur.com/uvF7ybU.jpeg , https://i.imgur.com/4UFnHhg.jpeg , https://imgur.com/yBDIUKl.jpeg, https://i.imgur.com/0McV52E.jpeg , https://i.imgur.com/ZfvQIV4.jpeg , https://imgur.com/US4kxwg.jpeg | E4: =IFERROR(MINIFS('Inventario barrios'!F:F,'Inventario barrios'!D:D,TRIM(A4),'Inventario barrios'!F:F,">0"),0) -> 260000000 | F4: =IFERROR(AVERAGEIFS('Inventario barrios'!F:F,'Inventario barrios'!D:D,TRIM(A4),'Inventario barrios'!F:F,">0"),0) -> 3.1857143e+08 | G4: =IFERROR(AVERAGEIFS('Inventario barrios'!J:J,'Inventario barrios'!D:D,TRIM(A4),'Inventario barrios'!J:J,">0"),0) -> 0 | H4: =IFERROR(AVERAGEIFS('Inventario barrios'!K:K,'Inventario barrios'!D:D,TRIM(A4),'Inventario barrios'!K:K,">0"),0) -> 0 | I4: =IFERROR(AVERAGEIFS('Inventario barrios'!N:N,'Inventario barrios'!D:D,TRIM(A4),'Inventario barrios'!N:N,">0"),0) -> 3 | J4: 4
A5: Villa Carolina | B5: Centro comercial San Pedro Plaza , Centro comercial San Juan Plaza , Supermercado Olímpica , Homecenter , Parroquia Santa María de la Paz , Centro de atención integral materno infantil CAIMI , | C5: https://sanpedroplazacomercial.com.co/ , https://sanjuanplazacc.com/ , https://www.olimpica.com/nuestras-tiendas/ , https://www.homecenter.com.co/homecenter-co/ , https://diocesisdeneiva.org/directorio/parroquias/Santa-Maria-de-la-Paz-Neiva , https://esecarmenemiliaospina.gov.co/el-corazon-del-caimi-ya-esta-listo/ , | D5: https://i.imgur.com/0McV52E.jpeg , https://i.imgur.com/NqTPCOW.jpeg , https://i.imgur.com/LTJ6cm8.jpeg , https://i.imgur.com/ZfvQIV4.jpeg , https://i.imgur.com/2jLDNZK.jpeg , https://i.imgur.com/6K5qkDD.jpeg , https://i.imgur.com/2CK2QZ7.jpeg , https://i.imgur.com/5wEmeiL.jpeg , | E5: =IFERROR(MINIFS('Inventario barrios'!F:F,'Inventario barrios'!D:D,TRIM(A5),'Inventario barrios'!F:F,">0"),0) -> 120000000 | F5: =IFERROR(AVERAGEIFS('Inventario barrios'!F:F,'Inventario barrios'!D:D,TRIM(A5),'Inventario barrios'!F:F,">0"),0) -> 3.3333333e+08 | G5: =IFERROR(AVERAGEIFS('Inventario barrios'!J:J,'Inventario barrios'!D:D,TRIM(A5),'Inventario barrios'!J:J,">0"),0) -> 0 | H5: =IFERROR(AVERAGEIFS('Inventario barrios'!K:K,'Inventario barrios'!D:D,TRIM(A5),'Inventario barrios'!K:K,">0"),0) -> 0 | I5: =IFERROR(AVERAGEIFS('Inventario barrios'!N:N,'Inventario barrios'!D:D,TRIM(A5),'Inventario barrios'!N:N,">0"),0) -> 3.1428571 | J5: 5
A6: Villa Urbe | B6: Centro comercial San Pedro Plaza , Centro comercial San Juan Plaza , Supermercado Olímpica , Homecenter , Parroquia Santa María de la Paz , Centro de atención integral materno infantil CAIMI , | C6: https://sanpedroplazacomercial.com.co/ , https://sanjuanplazacc.com/ , https://www.olimpica.com/nuestras-tiendas/ , https://www.homecenter.com.co/homecenter-co/ , https://diocesisdeneiva.org/directorio/parroquias/Santa-Maria-de-la-Paz-Neiva , https://esecarmenemiliaospina.gov.co/el-corazon-del-caimi-ya-esta-listo/ , | D6: https://i.imgur.com/0McV52E.jpeg , https://i.imgur.com/NqTPCOW.jpeg , https://i.imgur.com/LTJ6cm8.jpeg , https://i.imgur.com/ZfvQIV4.jpeg , https://i.imgur.com/2jLDNZK.jpeg , https://i.imgur.com/6K5qkDD.jpeg , https://i.imgur.com/2CK2QZ7.jpeg , https://i.imgur.com/5wEmeiL.jpeg , | E6: =IFERROR(MINIFS('Inventario barrios'!F:F,'Inventario barrios'!D:D,TRIM(A6),'Inventario barrios'!F:F,">0"),0) -> 240000000 | F6: =IFERROR(AVERAGEIFS('Inventario barrios'!F:F,'Inventario barrios'!D:D,TRIM(A6),'Inventario barrios'!F:F,">0"),0) -> 280000000 | G6: =IFERROR(AVERAGEIFS('Inventario barrios'!J:J,'Inventario barrios'!D:D,TRIM(A6),'Inventario barrios'!J:J,">0"),0) -> 0 | H6: =IFERROR(AVERAGEIFS('Inventario barrios'!K:K,'Inventario barrios'!D:D,TRIM(A6),'Inventario barrios'!K:K,">0"),0) -> 0 | I6: =IFERROR(AVERAGEIFS('Inventario barrios'!N:N,'Inventario barrios'!D:D,TRIM(A6),'Inventario barrios'!N:N,">0"),0) -> 3.5 | J6: 2
A7: Alamos Norte | B7: Centro comercial San Pedro Plaza , Centrocomercial San Juan Plaza , Homecenter , Parroquia Santa María de la Paz , Centro de atención integral materno infantil CAIMI , | C7: https://sanpedroplazacomercial.com.co/ , https://sanjuanplazacc.com/ , https://www.olimpica.com/nuestras-tiendas/ , https://www.homecenter.com.co/homecenter-co/ , https://diocesisdeneiva.org/directorio/parroquias/Santa-Maria-de-la-Paz-Neiva , https://esecarmenemiliaospina.gov.co/el-corazon-del-caimi-ya-esta-listo/ , | D7: https://i.imgur.com/0McV52E.jpeg , https://i.imgur.com/NqTPCOW.jpeg , https://i.imgur.com/LTJ6cm8.jpeg , https://i.imgur.com/ZfvQIV4.jpeg , https://i.imgur.com/6K5qkDD.jpeg , https://i.imgur.com/2CK2QZ7.jpeg , https://i.imgur.com/5wEmeiL.jpeg , | E7: =IFERROR(MINIFS('Inventario barrios'!F:F,'Inventario barrios'!D:D,TRIM(A7),'Inventario barrios'!F:F,">0"),0) -> 140000000 | F7: =IFERROR(AVERAGEIFS('Inventario barrios'!F:F,'Inventario barrios'!D:D,TRIM(A7),'Inventario barrios'!F:F,">0"),0) -> 390000000 | G7: =IFERROR(AVERAGEIFS('Inventario barrios'!J:J,'Inventario barrios'!D:D,TRIM(A7),'Inventario barrios'!J:J,">0"),0) -> 0 | H7: =IFERROR(AVERAGEIFS('Inventario barrios'!K:K,'Inventario barrios'!D:D,TRIM(A7),'Inventario barrios'!K:K,">0"),0) -> 0 | I7: =IFERROR(AVERAGEIFS('Inventario barrios'!N:N,'Inventario barrios'!D:D,TRIM(A7),'Inventario barrios'!N:N,">0"),0) -> 4.2 | J7: 3
A8: Santa Librada | B8: Estadio Guillermo Plazas Alcid , INDER , Batallón Tenerife , Comando Policia Nacional , Hospital Universitario Hernando Moncaleano Perdomo , Colegio Santa Librada , | C8: https://clubatleticohuila.com.co/ , https://inderhuila.gov.co/crd/ , https://www.cgfm.mil.co/es/taxonomy/term/13625 , https://www.policia.gov.co/neiva , https://hospitalneiva.gov.co/ , https://www.santalibradaneiva.edu.co/ , | D8: https://imgur.com/hN630gp.jpeg , https://imgur.com/PNtFJ9l.jpeg , https://imgur.com/Vg1js9v.jpeg , https://imgur.com/t2uszmF.jpeg , https://imgur.com/DoTgP2s.jpeg , https://imgur.com/fcJveEr.jpeg | E8: =IFERROR(MINIFS('Inventario barrios'!F:F,'Inventario barrios'!D:D,TRIM(A8),'Inventario barrios'!F:F,">0"),0) -> 130000000 | F8: =IFERROR(AVERAGEIFS('Inventario barrios'!F:F,'Inventario barrios'!D:D,TRIM(A8),'Inventario barrios'!F:F,">0"),0) -> 373000000 | G8: =IFERROR(AVERAGEIFS('Inventario barrios'!J:J,'Inventario barrios'!D:D,TRIM(A8),'Inventario barrios'!J:J,">0"),0) -> 0 | H8: =IFERROR(AVERAGEIFS('Inventario barrios'!K:K,'Inventario barrios'!D:D,TRIM(A8),'Inventario barrios'!K:K,">0"),0) -> 0 | I8: =IFERROR(AVERAGEIFS('Inventario barrios'!N:N,'Inventario barrios'!D:D,TRIM(A8),'Inventario barrios'!N:N,">0"),0) -> 3.5 | J8: 4
A9: Chapinero | B9: Estadio Guillermo Plazas Alcid , INDER , Batallón Tenerife , Comando Policia Nacional , Hospital Universitario Hernando Moncaleano Perdomo , Colegio Santa Librada , | C9: https://clubatleticohuila.com.co/ , https://inderhuila.gov.co/crd/ , https://www.cgfm.mil.co/es/taxonomy/term/13625 , https://www.policia.gov.co/neiva , https://hospitalneiva.gov.co/ , https://www.santalibradaneiva.edu.co/ , | D9: https://imgur.com/hN630gp.jpeg , https://imgur.com/PNtFJ9l.jpeg , https://imgur.com/Vg1js9v.jpeg , https://imgur.com/t2uszmF.jpeg , https://imgur.com/DoTgP2s.jpeg , https://imgur.com/fcJveEr.jpeg , | E9: =IFERROR(MINIFS('Inventario barrios'!F:F,'Inventario barrios'!D:D,TRIM(A9),'Inventario barrios'!F:F,">0"),0) -> 130000000 | F9: =IFERROR(AVERAGEIFS('Inventario barrios'!F:F,'Inventario barrios'!D:D,TRIM(A9),'Inventario barrios'!F:F,">0"),0) -> 4.6934783e+08 | G9: =IFERROR(AVERAGEIFS('Inventario barrios'!J:J,'Inventario barrios'!D:D,TRIM(A9),'Inventario barrios'!J:J,">0"),0) -> 0 | H9: =IFERROR(AVERAGEIFS('Inventario barrios'!K:K,'Inventario barrios'!D:D,TRIM(A9),'Inventario barrios'!K:K,">0"),0) -> 0 | I9: =IFERROR(AVERAGEIFS('Inventario barrios'!N:N,'Inventario barrios'!D:D,TRIM(A9),'Inventario barrios'!N:N,">0"),0) -> 2.65 | J9: 3
A10: Campo Nuñez | B10: Parroquia Nuestra Señora del Perpetuo Socorro , Panadería Peter Pan , Bomberos , Supermercado Popular , Batallón Tenerife , Comando Policia Nacional | C10: https://diocesisdeneiva.org/directorio/parroquias/Nuestra-Senora-del-Perpetuo-Socorro-Neiva , https://peterpan24horas.com/ , https://cbvn.com.co/ , https://www.instagram.com/supermercados_popular/?hl=es , https://www.cgfm.mil.co/es/taxonomy/term/13625 , https://www.policia.gov.co/neiva | D10: https://imgur.com/C5ubqD4.jpeg , https://imgur.com/lx4imr6.jpeg , https://imgur.com/7H6c5V3.jpeg , https://imgur.com/bEUf3pk.jpeg , https://imgur.com/Vg1js9v.jpeg , https://imgur.com/t2uszmF.jpeg | E10: =IFERROR(MINIFS('Inventario barrios'!F:F,'Inventario barrios'!D:D,TRIM(A10),'Inventario barrios'!F:F,">0"),0) -> 260000000 | F10: =IFERROR(AVERAGEIFS('Inventario barrios'!F:F,'Inventario barrios'!D:D,TRIM(A10),'Inventario barrios'!F:F,">0"),0) -> 4.8954545e+08 | G10: =IFERROR(AVERAGEIFS('Inventario barrios'!J:J,'Inventario barrios'!D:D,TRIM(A10),'Inventario barrios'!J:J,">0"),0) -> 0 | H10: =IFERROR(AVERAGEIFS('Inventario barrios'!K:K,'Inventario barrios'!D:D,TRIM(A10),'Inventario barrios'!K:K,">0"),0) -> 0 | I10: =IFERROR(AVERAGEIFS('Inventario barrios'!N:N,'Inventario barrios'!D:D,TRIM(A10),'Inventario barrios'!N:N,">0"),0) -> 2.5 | J10: 2
A11: La Toma | B11: Parroquia Nuestra Señora del Perpetuo Socorro , Panadería Peter Pan , Bomberos , Hospital Universitario Hernando Moncaleano Perdomo , Batallón Tenerife , Comando Policia Nacional | C11: https://diocesisdeneiva.org/directorio/parroquias/Nuestra-Senora-del-Perpetuo-Socorro-Neiva , https://peterpan24horas.com/ , https://cbvn.com.co/ , https://hospitalneiva.gov.co/ , https://www.cgfm.mil.co/es/taxonomy/term/13625 , https://www.policia.gov.co/neiva | D11: https://imgur.com/C5ubqD4.jpeg , https://imgur.com/lx4imr6.jpeg , https://imgur.com/7H6c5V3.jpeg , https://imgur.com/DoTgP2s.jpeg , https://imgur.com/Vg1js9v.jpeg , https://imgur.com/t2uszmF.jpeg | E11: =IFERROR(MINIFS('Inventario barrios'!F:F,'Inventario barrios'!D:D,TRIM(A11),'Inventario barrios'!F:F,">0"),0) -> 140000000 | F11: =IFERROR(AVERAGEIFS('Inventario barrios'!F:F,'Inventario barrios'!D:D,TRIM(A11),'Inventario barrios'!F:F,">0"),0) -> 7.6193543e+08 | G11: =IFERROR(AVERAGEIFS('Inventario barrios'!J:J,'Inventario barrios'!D:D,TRIM(A11),'Inventario barrios'!J:J,">0"),0) -> 0 | H11: =IFERROR(AVERAGEIFS('Inventario barrios'!K:K,'Inventario barrios'!D:D,TRIM(A11),'Inventario barrios'!K:K,">0"),0) -> 0 | I11: =IFERROR(AVERAGEIFS('Inventario barrios'!N:N,'Inventario barrios'!D:D,TRIM(A11),'Inventario barrios'!N:N,">0"),0) -> 2.5862069 | J11: 2
A12: Quirinal | B12: Centro de convenciones José Eustacio Rivera, Clínica UROS, Universidad CORHUILA, Supermercado Olímpica, Supermercado Metro, Servicio Nacional de Aprendizaje (SENA) | C12: https://www.huila.gov.co/publicaciones/12480/el-centro-de-convenciones-jose-eustasio-rivera-y-el-recinto-ferial-la-voragine-epicentros-de-la-programacion-del-san-pedro/ , https://clinicauros.com/ , https://corhuila.edu.co/ , https://www.olimpica.com/nuestras-tiendas/ , https://ofertas.tiendasmetro.co/ubicaciones/ , https://www.sena.edu.co/es-co/Paginas/default.aspx | D12: https://imgur.com/QoxdRse.jpeg , https://imgur.com/wuiOM6H.jpeg , https://imgur.com/zVU1my4.jpeg , https://imgur.com/o1FG3ZC.jpeg , https://imgur.com/lWTCCyb.jpeg , https://imgur.com/bgMDBtx.jpeg | E12: =IFERROR(MINIFS('Inventario barrios'!F:F,'Inventario barrios'!D:D,TRIM(A12),'Inventario barrios'!F:F,">0"),0) -> 300000000 | F12: =IFERROR(AVERAGEIFS('Inventario barrios'!F:F,'Inventario barrios'!D:D,TRIM(A12),'Inventario barrios'!F:F,">0"),0) -> 8.0138889e+08 | G12: =IFERROR(AVERAGEIFS('Inventario barrios'!J:J,'Inventario barrios'!D:D,TRIM(A12),'Inventario barrios'!J:J,">0"),0) -> 0 | H12: =IFERROR(AVERAGEIFS('Inventario barrios'!K:K,'Inventario barrios'!D:D,TRIM(A12),'Inventario barrios'!K:K,">0"),0) -> 0 | I12: =IFERROR(AVERAGEIFS('Inventario barrios'!N:N,'Inventario barrios'!D:D,TRIM(A12),'Inventario barrios'!N:N,">0"),0) -> 4.2941176 | J12: 4
A13: Sevilla | B13: Centro de convenciones José Eustacio Rivera, Clínica UROS, Universidad CORHUILA, Supermercado Olímpica, Supermercado Metro, Panadería Peter Pan | C13: https://www.huila.gov.co/publicaciones/12480/el-centro-de-convenciones-jose-eustasio-rivera-y-el-recinto-ferial-la-voragine-epicentros-de-la-programacion-del-san-pedro/ , https://clinicauros.com/ , https://corhuila.edu.co/ , https://www.olimpica.com/nuestras-tiendas/ , https://ofertas.tiendasmetro.co/ubicaciones/ , https://peterpan24horas.com/ | D13: https://imgur.com/QoxdRse.jpeg , https://imgur.com/wuiOM6H.jpeg , https://imgur.com/zVU1my4.jpeg , https://imgur.com/o1FG3ZC.jpeg , https://imgur.com/lWTCCyb.jpeg , https://imgur.com/lx4imr6.jpeg | E13: =IFERROR(MINIFS('Inventario barrios'!F:F,'Inventario barrios'!D:D,TRIM(A13),'Inventario barrios'!F:F,">0"),0) -> 250000000 | F13: =IFERROR(AVERAGEIFS('Inventario barrios'!F:F,'Inventario barrios'!D:D,TRIM(A13),'Inventario barrios'!F:F,">0"),0) -> 6.1631579e+08 | G13: =IFERROR(AVERAGEIFS('Inventario barrios'!J:J,'Inventario barrios'!D:D,TRIM(A13),'Inventario barrios'!J:J,">0"),0) -> 0 | H13: =IFERROR(AVERAGEIFS('Inventario barrios'!K:K,'Inventario barrios'!D:D,TRIM(A13),'Inventario barrios'!K:K,">0"),0) -> 0 | I13: =IFERROR(AVERAGEIFS('Inventario barrios'!N:N,'Inventario barrios'!D:D,TRIM(A13),'Inventario barrios'!N:N,">0"),0) -> 3.7777778 | J13: 5
G36: =IF(TRIM(H18)=TRIM($A18), D18, )
G37: =IF(TRIM(H19)=TRIM($A19), D19, )
G38: =IF(TRIM(H20)=TRIM($A20), D20, )
G39: =IF(TRIM(H21)=TRIM($A21), D21, )
G40: =IF(TRIM(H22)=TRIM($A22), D22, )
G41: =IF(TRIM(H23)=TRIM($A23), D23, )

Sheet Inventario barrios
A1: =IFERROR(__xludf.DUMMYFUNCTION("FILTER('Base de Datos'!A1:BF3379, 'Base de Datos'!AH1:AH3379=""Inventario"")"),"Código") -> Código | B1: =IFERROR(__xludf.DUMMYFUNCTION("""COMPUTED_VALUE"""),"Nombre") -> Nombre | C1: =IFERROR(__xludf.DUMMYFUNCTION("""COMPUTED_VALUE"""),"Tipo de inmueble") -> Tipo de inmueble | D1: =IFERROR(__xludf.DUMMYFUNCTION("""COMPUTED_VALUE"""),"Barrio") -> Barrio | E1: =IFERROR(__xludf.DUMMYFUNCTION("""COMPUTED_VALUE"""),"Conjunto") -> Conjunto | F1: =IFERROR(__xludf.DUMMYFUNCTION("""COMPUTED_VALUE"""),"Precio") -> Precio | G1: =IFERROR(__xludf.DUMMYFUNCTION("""COMPUTED_VALUE"""),"Rango de precio") -> Rango de precio | H1: =IFERROR(__xludf.DUMMYFUNCTION("""COMPUTED_VALUE"""),"Hipoteca") -> Hipoteca | I1: =IFERROR(__xludf.DUMMYFUNCTION("""COMPUTED_VALUE"""),"Permuta") -> Permuta | J1: =IFERROR(__xludf.DUMMYFUNCTION("""COMPUTED_VALUE"""),"Zona") -> Zona | K1: =IFERROR(__xludf.DUMMYFUNCTION("""COMPUTED_VALUE"""),"Comuna") -> Comuna | L1: =IFERROR(__xludf.DUMMYFUNCTION("""COMPUTED_VALUE"""),"Habitaciones") -> Habitaciones | M1: =IFERROR(__xludf.DUMMYFUNCTION("""COMPUTED_VALUE"""),"Habitacion en 1er piso") -> Habitacion en 1er piso | N1: =IFERROR(__xludf.DUMMYFUNCTION("""COMPUTED_VALUE"""),"Baños") -> Baños | O1: =IFERROR(__xludf.DUMMYFUNCTION("""COMPUTED_VALUE"""),"Garaje") -> Garaje | P1: =IFERROR(__xludf.DUMMYFUNCTION("""COMPUTED_VALUE"""),"Pisos") -> Pisos | Q1: =IFERROR(__xludf.DUMMYFUNCTION("""COMPUTED_VALUE"""),"Área Construida") -> Área Construida | R1: =IFERROR(__xludf.DUMMYFUNCTION("""COMPUTED_VALUE"""),"Área lote") -> Área lote | S1: =IFERROR(__xludf.DUMMYFUNCTION("""COMPUTED_VALUE"""),"Rentabilidad") -> Rentabilidad | T1: =IFERROR(__xludf.DUMMYFUNCTION("""COMPUTED_VALUE"""),"Ciudad") -> Ciudad | U1: =IFERROR(__xludf.DUMMYFUNCTION("""COMPUTED_VALUE"""),"Estrato") -> Estrato | V1: =IFERROR(__xludf.DUMMYFUNCTION("""COMPUTED_VALUE"""),"Ubicación") -> Ubicación | W1: =IFERROR(__xludf.DUMMYFUNCTION("""COMPUTED_VALUE"""),"Vía") -> Vía | X1: =IFERROR(__xludf.DUMMYFUNCTION("""COMPUTED_VALUE"""),"Closet") -> Closet | Y1: =IFERROR(__xludf.DUMMYFUNCTION("""COMPUTED_VALUE"""),"Piscina") -> Piscina | Z1: =IFERROR(__xludf.DUMMYFUNCTION("""COMPUTED_VALUE"""),"Administración") -> Administración | AA1: =IFERROR(__xludf.DUMMYFUNCTION("""COMPUTED_VALUE"""),"Retorno de la Inversión") -> Retorno de la Inversión | AB1: =IFERROR(__xludf.DUMMYFUNCTION("""COMPUTED_VALUE"""),"Google Fotos") -> Google Fotos | AC1: =IFERROR(__xludf.DUMMYFUNCTION("""COMPUTED_VALUE"""),"Descripción") -> Descripción | AD1: =IFERROR(__xludf.DUMMYFUNCTION("""COMPUTED_VALUE"""),"Puntos Clave") -> Puntos Clave | AE1: =IFERROR(__xludf.DUMMYFUNCTION("""COMPUTED_VALUE"""),"Buscar") -> Buscar | AF1: =IFERROR(__xludf.DUMMYFUNCTION("""COMPUTED_VALUE"""),"Cocina") -> Cocina | AG1: =IFERROR(__xludf.DUMMYFUNCTION("""COMPUTED_VALUE"""),"Publicar") -> Publicar | AH1: =IFERROR(__xludf.DUMMYFUNCTION("""COMPUTED_VALUE"""),"Inventario") -> Inventario | AI1: =IFERROR(__xludf.DUMMYFUNCTION("""COMPUTED_VALUE"""),"Contrato") -> Contrato | AJ1: =IFERROR(__xludf.DUMMYFUNCTION("""COMPUTED_VALUE"""),"Inmobiliaria") -> Inmobiliaria | AK1: =IFERROR(__xludf.DUMMYFUNCTION("""COMPUTED_VALUE"""),"Estado del contrato Firmados - para imprimir - sin contrato") -> Estado del contrato Firmados - para imprimir - sin contrato | AL1: =IFERROR(__xludf.DUMMYFUNCTION("""COMPUTED_VALUE"""),"TIENE FOTOS - CODIGOS DISPONIBLES-NO TIENE FOTOS-NUEVOS ULTIMOS BARRIDOS - FIRMO CONTRATO ICDE") -> TIENE FOTOS - CODIGOS DISPONIBLES-NO TIENE FOTOS-NUEVOS ULTIMOS BARRIDOS - FIRMO CONTRATO ICDE | AM1: =IFERROR(__xludf.DUMMYFUNCTION("""COMPUTED_VALUE"""),"CELULAR") -> CELULAR | AN1: =IFERROR(__xludf.DUMMYFUNCTION("""COMPUTED_VALUE"""),"CELULAR 2") -> CELULAR 2 | AO1: =IFERROR(__xludf.DUMMYFUNCTION("""COMPUTED_VALUE"""),"PROPIETARIO") -> PROPIETARIO | AP1: =IFERROR(__xludf.DUMMYFUNCTION("""COMPUTED_VALUE"""),"DIRECCIÓN") -> DIRECCIÓN | AQ1: =IFERROR(__xludf.DUMMYFUNCTION("""COMPUTED_VALUE"""),"LATITUD") -> LATITUD | AR1: =IFERROR(__xludf.DUMMYFUNCTION("""COMPUTED_VALUE"""),"LONGITUD") -> LONGITUD | AS1: =IFERROR(__xludf.DUMMYFUNCTION("""COMPUTED_VALUE"""),"RENTAB.") -> RENTAB. | AT1: =IFERROR(__xludf.DUMMYFUNCTION("""COMPUTED_VALUE"""),"ASCENSOR") -> ASCENSOR | AU1: =IFERROR(__xludf.DUMMYFUNCTION("""COMPUTED_VALUE"""),"CORTINAS") -> CORTINAS | AV1: =IFERROR(__xludf.DUMMYFUNCTION("""COMPUTED_VALUE"""),"AIRE ACONDICIONADO") -> AIRE ACONDICIONADO | AW1: =IFERROR(__xludf.DUMMYFUNCTION("""COMPUTED_VALUE"""),"REJA/ ANTEJARDIN") -> REJA/ ANTEJARDIN | AX1: =IFERROR(__xludf.DUMMYFUNCTION("""COMPUTED_VALUE"""),"ANTIGÜEDAD") -> ANTIGÜEDAD | AY1: =IFERROR(__xludf.DUMMYFUNCTION("""COMPUTED_VALUE"""),"PATIO") -> PATIO | AZ1: =IFERROR(__xludf.DUMMYFUNCTION("""COMPUTED_VALUE"""),"DIMENSIONES") -> DIMENSIONES | BC1: =IFERROR(__xludf.DUMMYFUNCTION("""COMPUTED_VALUE"""),"LEADS ASIGNADOS") -> LEADS ASIGNADOS | BD1: =IFERROR(__xludf.DUMMYFUNCTION("""COMPUTED_VALUE"""),"g0f") -> g0f | BE1: =IFERROR(__xludf.DUMMYFUNCTION("""COMPUTED_VALUE"""),"PROPUESTAS SUGERIDAS POR IA") -> PROPUESTAS SUGERIDAS POR IA | BF1: =IFERROR(__xludf.DUMMYFUNCTION("""COMPUTED_VALUE"""),"Imagenes") -> Imagenes
A2: =IFERROR(__xludf.DUMMYFUNCTION("""COMPUTED_VALUE"""),"7064") -> 7064 | B2: =IFERROR(__xludf.DUMMYFUNCTION("""COMPUTED_VALUE"""),"Casa en barrio La Toma") -> Casa en barrio La Toma | C2: =IFERROR(__xludf.DUMMYFUNCTION("""COMPUTED_VALUE"""),"Casa") -> Casa | D2: =IFERROR(__xludf.DUMMYFUNCTION("""COMPUTED_VALUE"""),"La Toma") -> La Toma | F2: =IFERROR(__xludf.DUMMYFUNCTION("""COMPUTED_VALUE"""),2.5E8) -> 250000000 | G2: =IFERROR(__xludf.DUMMYFUNCTION("""COMPUTED_VALUE"""),"$200'000.000 a $300'000.000") -> $200'000.000 a $300'000.000 | J2: =IFERROR(__xludf.DUMMYFUNCTION("""COMPUTED_VALUE"""),"Centro") -> Centro | K2: =IFERROR(__xludf.DUMMYFUNCTION("""COMPUTED_VALUE"""),"3") -> 3 | L2: =IFERROR(__xludf.DUMMYFUNCTION("""COMPUTED_VALUE"""),4.0) -> 4 | N2: =IFERROR(__xludf.DUMMYFUNCTION("""COMPUTED_VALUE"""),2.0) -> 2 | O2: =IFERROR(__xludf.DUMMYFUNCTION("""COMPUTED_VALUE"""),0.0) -> 0 | P2: =IFERROR(__xludf.DUMMYFUNCTION("""COMPUTED_VALUE"""),1.0) -> 1 | Q2: =IFERROR(__xludf.DUMMYFUNCTION("""COMPUTED_VALUE"""),117.0) -> 117 | R2: =IFERROR(__xludf.DUMMYFUNCTION("""COMPUTED_VALUE"""),146.0) -> 146 | S2: =IFERROR(__xludf.DUMMYFUNCTION("""COMPUTED_VALUE"""),"Rentabilidad $950,000") -> Rentabilidad $950,000 | T2: =IFERROR(__xludf.DUMMYFUNCTION("""COMPUTED_VALUE"""),"Neiva") -> Neiva | U2: =IFERROR(__xludf.DUMMYFUNCTION("""COMPUTED_VALUE"""),"3") -> 3 | V2: =IFERROR(__xludf.DUMMYFUNCTION("""COMPUTED_VALUE"""),"Medianera") -> Medianera | X2: =IFERROR(__xludf.DUMMYFUNCTION("""COMPUTED_VALUE"""),0.0) -> 0 | Y2: =IFERROR(__xludf.DUMMYFUNCTION("""COMPUTED_VALUE"""),"No tiene") -> No tiene | Z2: =IFERROR(__xludf.DUMMYFUNCTION("""COMPUTED_VALUE"""),"No aplica") -> No aplica | AA2: =IFERROR(__xludf.DUMMYFUNCTION("""COMPUTED_VALUE"""),"22 años") -> 22 años | AF2: =IFERROR(__xludf.DUMMYFUNCTION("""COMPUTED_VALUE"""),"básica") -> básica | AH2: =IFERROR(__xludf.DUMMYFUNCTION("""COMPUTED_VALUE"""),"Inventario") -> Inventario | AJ2: =IFERROR(__xludf.DUMMYFUNCTION("""COMPUTED_VALUE""")," F/$250") -> F/$250 | AK2: =IFERROR(__xludf.DUMMYFUNCTION("""COMPUTED_VALUE"""),"No aplica") -> No aplica | AL2: =IFERROR(__xludf.DUMMYFUNCTION("""COMPUTED_VALUE"""),"NO FOTOS + DESCRIPCION") -> NO FOTOS + DESCRIPCION | AM2: =IFERROR(__xludf.DUMMYFUNCTION("""COMPUTED_VALUE"""),3.183955563E9) -> 3183955563 | AP2: =IFERROR(__xludf.DUMMYFUNCTION("""COMPUTED_VALUE"""),"CARRERA 7 A No. 13 - 20") -> CARRERA 7 A No. 13 - 20 | AS2: =IFERROR(__xludf.DUMMYFUNCTION("""COMPUTED_VALUE"""),950000.0) -> 950000 | AT2: =IFERROR(__xludf.DUMMYFUNCTION("""COMPUTED_VALUE"""),0.0) -> 0 | AU2: =IFERROR(__xludf.DUMMYFUNCTION("""COMPUTED_VALUE"""),0.0) -> 0 | AV2: =IFERROR(__xludf.DUMMYFUNCTION("""COMPUTED_VALUE"""),0.0) -> 0 | AW2: =IFERROR(__xludf.DUMMYFUNCTION("""COMPUTED_VALUE"""),"NO") -> NO | AX2: =IFERROR(__xludf.DUMMYFUNCTION("""COMPUTED_VALUE"""),0.0) -> 0 | AY2: =IFERROR(__xludf.DUMMYFUNCTION("""COMPUTED_VALUE"""),0.0) -> 0 | AZ2: =IFERROR(__xludf.DUMMYFUNCTION("""COMPUTED_VALUE"""),0.0) -> 0 | BA2: =IFERROR(__xludf.DUMMYFUNCTION("""COMPUTED_VALUE"""),"X") -> X | BB2: =IFERROR(__xludf.DUMMYFUNCTION("""COMPUTED_VALUE"""),0.0) -> 0 | BC2: =IFERROR(__xludf.DUMMYFUNCTION("""COMPUTED_VALUE"""),"20 - SAMADHI RODRIGUEZ") -> 20 - SAMADHI RODRIGUEZ
A3: =IFERROR(__xludf.DUMMYFUNCTION("""COMPUTED_VALUE"""),"3084") -> 3084 | B3: =IFERROR(__xludf.DUMMYFUNCTION("""COMPUTED_VALUE"""),"Casa en barrio Campo Nuñez") -> Casa en barrio Campo Nuñez | C3: =IFERROR(__xludf.DUMMYFUNCTION("""COMPUTED_VALUE"""),"Casa") -> Casa | D3: =IFERROR(__xludf.DUMMYFUNCTION("""COMPUTED_VALUE"""),"Campo Nuñez") -> Campo Nuñez | F3: =IFERROR(__xludf.DUMMYFUNCTION("""COMPUTED_VALUE"""),7.0E8) -> 700000000 | G3: =IFERROR(__xludf.DUMMYFUNCTION("""COMPUTED_VALUE"""),"$500'000.000 a $1.000'000.000") -> $500'000.000 a $1.000'000.000 | J3: =IFERROR(__xludf.DUMMYFUNCTION("""COMPUTED_VALUE"""),"Centro") -> Centro | K3: =IFERROR(__xludf.DUMMYFUNCTION("""COMPUTED_VALUE"""),"3") -> 3 | L3: =IFERROR(__xludf.DUMMYFUNCTION("""COMPUTED_VALUE"""),4.0) -> 4 | N3: =IFERROR(__xludf.DUMMYFUNCTION("""COMPUTED_VALUE"""),3.0) -> 3 | O3: =IFERROR(__xludf.DUMMYFUNCTION("""COMPUTED_VALUE"""),1.0) -> 1 | P3: =IFERROR(__xludf.DUMMYFUNCTION("""COMPUTED_VALUE"""),1.0) -> 1 | Q3: =IFERROR(__xludf.DUMMYFUNCTION("""COMPUTED_VALUE"""),210.0) -> 210 | R3: =IFERROR(__xludf.DUMMYFUNCTION("""COMPUTED_VALUE"""),210.0) -> 210 | S3: =IFERROR(__xludf.DUMMYFUNCTION("""COMPUTED_VALUE""")," ") | T3: =IFERROR(__xludf.DUMMYFUNCTION("""COMPUTED_VALUE"""),"Neiva") -> Neiva | U3: =IFERROR(__xludf.DUMMYFUNCTION("""COMPUTED_VALUE"""),"4") -> 4 | V3: =IFERROR(__xludf.DUMMYFUNCTION("""COMPUTED_VALUE"""),"Medianera") -> Medianera | X3: =IFERROR(__xludf.DUMMYFUNCTION("""COMPUTED_VALUE"""),4.0) -> 4 | Y3: =IFERROR(__xludf.DUMMYFUNCTION("""COMPUTED_VALUE"""),"No tiene") -> No tiene | Z3: =IFERROR(__xludf.DUMMYFUNCTION("""COMPUTED_VALUE"""),"No aplica") -> No aplica | AA3: =IFERROR(__xludf.DUMMYFUNCTION("""COMPUTED_VALUE"""),"No aplica") -> No aplica | AB3: =IFERROR(__xludf.DUMMYFUNCTION("""COMPUTED_VALUE"""),"https://photos.app.goo.gl/zwhNZsro4YC2YDY28") -> https://photos.app.goo.gl/zwhNZsro4YC2YDY28 | AF3: =IFERROR(__xludf.DUMMYFUNCTION("""COMPUTED_VALUE"""),"semi-integral") -> semi-integral | AH3: =IFERROR(__xludf.DUMMYFUNCTION("""COMPUTED_VALUE"""),"Inventario") -> Inventario | AJ3: =IFERROR(__xludf.DUMMYFUNCTION("""COMPUTED_VALUE"""),"B-Inventario Campo Nuñez") -> B-Inventario Campo Nuñez | AL3: =IFERROR(__xludf.DUMMYFUNCTION("""COMPUTED_VALUE"""),"TIENE FOTOS") -> TIENE FOTOS | AM3: =IFERROR(__xludf.DUMMYFUNCTION("""COMPUTED_VALUE"""),3.212323681E9) -> 3212323681 | AN3: =IFERROR(__xludf.DUMMYFUNCTION("""COMPUTED_VALUE"""),3.135781638E9) -> 3135781638 | AP3: =IFERROR(__xludf.DUMMYFUNCTION("""COMPUTED_VALUE"""),"CARRERA 7A NO. 16-30") -> CARRERA 7A NO. 16-30 | AS3: =IFERROR(__xludf.DUMMYFUNCTION("""COMPUTED_VALUE"""),0.0) -> 0 | AT3: =IFERROR(__xludf.DUMMYFUNCTION("""COMPUTED_VALUE"""),0.0) -> 0 | AU3: =IFERROR(__xludf.DUMMYFUNCTION("""COMPUTED_VALUE"""),0.0) -> 0 | AV3: =IFERROR(__xludf.DUMMYFUNCTION("""COMPUTED_VALUE"""),0.0) -> 0 | AW3: =IFERROR(__xludf.DUMMYFUNCTION("""COMPUTED_VALUE"""),"NO") -> NO | AX3: =IFERROR(__xludf.DUMMYFUNCTION("""COMPUTED_VALUE"""),0.0) -> 0 | AY3: =IFERROR(__xludf.DUMMYFUNCTION("""COMPUTED_VALUE"""),0.0) -> 0 | AZ3: =IFERROR(__xludf.DUMMYFUNCTION("""COMPUTED_VALUE"""),0.0) -> 0 | BA3: =IFERROR(__xludf.DUMMYFUNCTION("""COMPUTED_VALUE"""),"X") -> X | BB3: =IFERROR(__xludf.DUMMYFUNCTION("""COMPUTED_VALUE"""),0.0) -> 0 | BF3: =IFERROR(__xludf.DUMMYFUNCTION("""COMPUTED_VALUE"""),"https://lh3.googleusercontent.com/pw/AP1GczM_q4YkeTMYSuUBWqqYdzZYkAC3FlC98d-y3b-Dx0lH7xec5m3GKCiMT3HyIGewfaeqjPMlkcPCbqyf9DOisePdzXfQ0uGd63iytM9TyJhAC4OhHWsI=w1200|https://lh3.googleusercontent.com/pw/AP1GczObcfnIuRHJEzsPXoEx4-mxe1p0-lcx2AALgAFjDcsd1siefk"&"9XT0EJ_WGP2t-ZwTXBN1E0rdsKqe3UK_7UOLqNLNNyeyCozcj1rChnQVOPNfPPvmZc=w1200|https://lh3.googleusercontent.com/pw/AP1GczNwECtrsa10y7rYCW7TPXNTwuig3Hu2iT9oQd34hd7PLreqOwQXOjz5HmVU2rr8h1XJfzONC8G_UPS4rALEMJOVKh3J-CBjj57LqRpOB95lNZTUQS87=w1200|https://lh3.google"&"usercontent.com/pw/AP1GczNKlgzMJuRgq68zknZTaklmxyVzawGcGGo8LqkqkncShaAPtO5MqLAyLJkrEqRSDnZ3Yt_c3z7NT5PIc1jMtb_T0lyKnrHW_ECk_cltmYbUZpVtWHow=w1200|https://lh3.googleusercontent.com/pw/AP1GczMdrPdD7s1bwof_7j0nRdJPKOEO_9KsDtHFMytNWX1eUYm_20huVfmW2l5CnWQVjYJo"&"yvQPSBN7ldIXkcuUOdiI64rj1WjhHJyIWR7JmtY8C_UCDSCQ=w1200|https://lh3.googleusercontent.com/pw/AP1GczOdAw75Pq4jnUqYpjqGoCI6Cram8907QZSDG175wPpYKIpYV-AvPYhmhMPpHs9ydM7DirObUReMJcXHb82kHOjGhKaZn5mvaKz5OTB-Vq9F9XKL11oy=w1200|https://lh3.googleusercontent.com/pw"&"/AP1GczN-cAD5LXmcicIOsdS1CPjvkCu1BopVQDyva-DehdTRxLyVNlGzrMOooj1wed2kwGxsm06zDPrNmqB9hTnqGzITQOArzi7whyJYF1matwc9zRf-9dH_=w1200|https://lh3.googleusercontent.com/pw/AP1GczNM_VjlEnV_fZCEWBs5qKgQqyzl54gqE5y8cbIYJkPYGqC05ul8D4YKwwOOxAtCzXTHgPRJy0Ie5tYMWJpjHr"&"SBJAg2PfRF5oHhfi2AeXXbixY4zSE7=w1200|https://lh3.googleusercontent.com/pw/AP1GczOozep_ElfpR77cAt2x2VNC6V0pIvCEaN0NRf18Q6NgXEfrUaGNFdVNefXu0GD7fA1lkuLK9o03-saz8IZeYe0PpL3niUR27EzF5jRx5KPq_8TevjHx=w1200|https://lh3.googleusercontent.com/pw/AP1GczM9ZLiKiO4fH"&"LZgea-iXR_KLPYulpe82VX6ZUZiHXiVLVvkp2BUb7jdbDAZYwz5zXS2ETgA-CmaVahxAd3HPcZe0By9lCLvippFZPs7VtQEUOVcRknO=w1200|https://lh3.googleusercontent.com/pw/AP1GczMu9dpvklZNNCDR3D0VItJFrW79NYF5upGnvOHJ5tkXRWmkGF9uwWFIV3lp9xKl6VSe7sR7Fpp21-pIYcoyyGYmQgtKF7N6vb3YXOJ4"&"mdfvSO18CghG=w1200|https://lh3.googleusercontent.com/pw/AP1GczPgb1Tbbxnqbi9-MiryvQ_45vxSnucSLN-EZpx1IzJsHjALiOlsTahw5w8oCshTCFLxK7Oar5k7mZaYVvXRmfQlZN2Horrs39uSMV3MLA--C101qHvC=w1200|https://lh3.googleusercontent.com/pw/AP1GczM9HE6nqOX2z3taUL-lXsItMNPj1PU"&"R6EbIHrPNK1RKxArKCi_yaX0zwpka7BWP3cJNGbk6wcBAB20Wwa5ynfuHs96j_vG9hLLQvo1r3_SOSKiZliML=w1200|https://lh3.googleusercontent.com/pw/AP1GczOofwiF-WFaC_9dWjhQtiUAKY_s8Uj1kuE9R5hqWc5l6aU2sEqDhOvL9vEhMWJfQgCUGzPEXVMFzcxFUjehtK7qeYemr5ECjIIDg7lSTb0tvfpT77vd=w1200"&"|https://lh3.googleusercontent.com/pw/AP1GczMxybDpjdsGE9lTGj1SC6_HBx8wASok0kRN2Mh8KT3CujwqTQsgUAXgv8S-XBHjwr2LYLWK2zvK-bD0ugxNxr8KQLD0YDqJdprZuXafGFuX_szQz4b9=w1200|https://lh3.googleusercontent.com/pw/AP1GczM4fNGtZ5skDT6kCIkR0ETNb7LG75DoAFlHP3Ki5CB7iaSGy"&"w5nN5LhaL2wXBnZ8VpGh9KHDXxUfPFR0oDdNDkVcyClcJ0ANPYECcD-_srowcDS-x80=w1200|https://lh3.googleusercontent.com/pw/AP1GczOeyzjIvWQl4Kh9tRuABHpSryYyQGLgL4Rkc5MRZ0VuhacnqqQ0gqF_6z6iOJvZyQwdEPmJ7kUy-_6UgjKAsBn1HKCD6mRh449Wd2T5zWHq08So3y9l=w1200|https://lh3.googl"&"eusercontent.com/pw/AP1GczPdT3tAmx7u0kTbY3JSvEzr4iLC2p9pky68ZTg1s4wwE9A03Koi7VLAiGmkTZVfYEXN_M6uVMxOpBikinflS9WFGaewR_josBtOyRnpY_9NMv5lmAx8=w1200|https://lh3.googleusercontent.com/pw/AP1GczMINMau5TM_f0_KXnV_4TWUU2lpYvgTczVrcTt5AYx-BJ-qJi_CPiI2kwVUdcXxMeB"&"0mCsT3K20ufY5TA4uFVj-yUruLvL9M24Gv4MgKkaO_0pUfxRP=w1200|https://lh3.googleusercontent.com/pw/AP1GczMu2kUh8u1pjOGGa1sCN7UM-GERUZxc9XAqpSSl09A4jMk5R7BoHWOF_VRYyNrJkrQzfSUk--fRwH1R3YkXxqrd7n4WiIKHeK0riX9CTB6Zg4lSSQf4=w1200|https://lh3.googleusercontent.com/p"&"w/AP1GczOca9e-Z7erZR73ga76_rnzoHcFYlPXhbnNtzDWud0oPMdJEQoxj-KZ1o7LlaFHJtX4jQL1H4FTwy3GQ_ChvdsARR-cpDTPLxbRmvgzO0ck-r1oJb77=w1200|https://lh3.googleusercontent.com/pw/AP1GczOoqcTA7Elg-8HYseVZ5V2z8FMJ4jv4UhV9Kh7Ci_8fQNlDCnD3DpKVF2nmexRq1lqCaSrJkJxNgSfVKzf1B"&"ucpve-cWbDySSUhYCVSgXgcRi2gk4ou=w1200|https://lh3.googleusercontent.com/pw/AP1GczOZyikEqhxenI-O0LmST7RMv_Wzw4g41Vf5Xpktl2zuGpyD_YpZGKfTqn3C63J1zL9oehpYgCQmc_Ry_iEhY1TYqofw6tha2EjndNFtaNSyJM4wjYWp=w1200|https://lh3.googleusercontent.com/pw/AP1GczO36Zy1EHB-"&"O1SvGcI50nz6BYJ70mVZ00hDk2Qm1dosPu4cOdzucLOPq1vtwwgBUcwKLDSb4OBAz-3xsYfZx1wllPxof0lehos40gM-ehM3SdfaVzeT=w1200|https://lh3.googleusercontent.com/pw/AP1GczNtKyAm_fQx_WJhVw-kMk1_q5912KxhSiW6pQfmyWh7HInIURo0aWuFhabc8cMEVoCuORI3gaaL9aPAT6zWcNCsTeKoLq0TNIyeAJH"&"d__Q0yDSG7Kg3=w1200") -> https://lh3.googleusercontent.com/pw/AP1GczM_q4YkeTMYSuUBWqqYdzZYkAC3FlC98d-y3b-Dx0lH7xec5m3GKCiMT3HyIGewfaeqjPMlkcPCbqyf9DOisePdzXfQ0uGd63iytM9TyJhAC4OhHWsI=w1200|https://lh3.googleusercontent.com/pw/AP1GczObcfnIuRHJEzsPXoEx4-mxe1p0-lcx2AALgAFjDcsd1siefk9XT0EJ_WGP2t-ZwTXBN1E0rdsKqe3UK_7UOLqNLNNyeyCozcj1rChnQVOPNfPPvmZc=w1200|https://lh3.googleusercontent.com/pw/AP1GczNwECtrsa10y7rYCW7TPXNTwuig3Hu2iT9oQd34hd7PLreqOwQXOjz5HmVU2rr8h1XJfzONC8G_UPS4rALEMJOVKh3J-CBjj57LqRpOB95lNZTUQS87=w1200|https://lh3.googleusercontent.com/pw/AP1GczNKlgzMJuRgq68zknZTaklmxyVzawGcGGo8LqkqkncShaAPtO5MqLAyLJkrEqRSDnZ3Yt_c3z7NT5PIc1jMtb_T0lyKnrHW_ECk_cltmYbUZpVtWHow=w1200|https://lh3.googleusercontent.com/pw/AP1GczMdrPdD7s1bwof_7j0nRdJPKOEO_9KsDtHFMytNWX1eUYm_20huVfmW2l5CnWQVjYJoyvQPSBN7ldIXkcuUOdiI64rj1WjhHJyIWR7JmtY8C_UCDSCQ=w1200|https://lh3.googleusercontent.com/pw/AP1GczOdAw75Pq4jnUqYpjqGoCI6Cram8907QZSDG175wPpYKIpYV-AvPYhmhMPpHs9ydM7DirObUReMJcXHb82kHOjGhKaZn5mvaKz5OTB-Vq9F9XKL11oy=w1200|https://lh3.googleusercontent.com/pw/AP1GczN-cAD5LXmcicIOsdS1CPjvkCu1BopVQDyva-DehdTRxLyVNlGzrMOooj1wed2kwGxsm06zDPrNmqB9hTnqGzITQOArzi7whyJYF1matwc9zRf-9dH_=w1200|https://lh3.googleusercontent.com/pw/AP1GczNM_VjlEnV_fZCEWBs5qKgQqyzl54gqE5y8cbIYJkPYGqC05ul8D4YKwwOOxAtCzXTHgPRJy0Ie5tYMWJpjHrSBJAg2PfRF5oHhfi2AeXXbixY4zSE7=w1200|https://lh3.googleusercontent.com/pw/AP1GczOozep_ElfpR77cAt2x2VNC6V0pIvCEaN0NRf18Q6NgXEfrUaGNFdVNefXu0GD7fA1lkuLK9o03-saz8IZeYe0PpL3niUR27EzF5jRx5KPq_8TevjHx=w1200|https://lh3.googleusercontent.com/pw/AP1GczM9ZLiKiO4fHLZgea-iXR_KLPYulpe82VX6ZUZiHXiVLVvkp2BUb7jdbDAZYwz5zXS2ETgA-CmaVahxAd3HPcZe0By9lCLvippFZPs7VtQEUOVcRknO=w1200|https://lh3.googleusercontent.com/pw/AP1GczMu9dpvklZNNCDR3D0VItJFrW79NYF5upGnvOHJ5tkXRWmkGF9uwWFIV3lp9xKl6VSe7sR7Fpp21-pIYcoyyGYmQgtKF7N6vb3YXOJ4mdfvSO18CghG=w1200|https://lh3.googleusercontent.com/pw/AP1GczPgb1Tbbxnqbi9-MiryvQ_45vxSnucSLN-EZpx1IzJsHjALiOlsTahw5w8oCshTCFLxK7Oar5k7mZaYVvXRmfQlZN2Horrs39uSMV3MLA--C101qHvC=w1200|https://lh3.googleusercontent.com/pw/AP1GczM9HE6nqOX2z3taUL-lXsItMNPj1PUR6EbIHrPNK1RKxArKCi_yaX0zwpka7BWP3cJNGbk6wcBAB20Wwa5ynfuHs96j_vG9hLLQvo1r3_SOSKiZliML=w1200|https://lh3.googleusercontent.com/pw/AP1GczOofwiF-WFaC_9dWjhQtiUAKY_s8Uj1kuE9R5hqWc5l6aU2sEqDhOvL9vEhMWJfQgCUGzPEXVMFzcxFUjehtK7qeYemr5ECjIIDg7lSTb0tvfpT77vd=w1200|https://lh3.googleusercontent.com/pw/AP1GczMxybDpjdsGE9lTGj1SC6_HBx8wASok0kRN2Mh8KT3CujwqTQsgUAXgv8S-XBHjwr2LYLWK2zvK-bD0ugxNxr8KQLD0YDqJdprZuXafGFuX_szQz4b9=w1200|https://lh3.googleusercontent.com/pw/AP1GczM4fNGtZ5skDT6kCIkR0ETNb7LG75DoAFlHP3Ki5CB7iaSGyw5nN5LhaL2wXBnZ8VpGh9KHDXxUfPFR0oDdNDkVcyClcJ0ANPYECcD-_srowcDS-x80=w1200|https://lh3.googleusercontent.com/pw/AP1GczOeyzjIvWQl4Kh9tRuABHpSryYyQGLgL4Rkc5MRZ0VuhacnqqQ0gqF_6z6iOJvZyQwdEPmJ7kUy-_6UgjKAsBn1HKCD6mRh449Wd2T5zWHq08So3y9l=w1200|https://lh3.googleusercontent.com/pw/AP1GczPdT3tAmx7u0kTbY3JSvEzr4iLC2p9pky68ZTg1s4wwE9A03Koi7VLAiGmkTZVfYEXN_M6uVMxOpBikinflS9WFGaewR_josBtOyRnpY_9NMv5lmAx8=w1200|https://lh3.googleusercontent.com/pw/AP1GczMINMau5TM_f0_KXnV_4TWUU2lpYvgTczVrcTt5AYx-BJ-qJi_CPiI2kwVUdcXxMeB0mCsT3K20ufY5TA4uFVj-yUruLvL9M24Gv4MgKkaO_0pUfxRP=w1200|https://lh3.googleusercontent.com/pw/AP1GczMu2kUh8u1pjOGGa1sCN7UM-GERUZxc9XAqpSSl09A4jMk5R7BoHWOF_VRYyNrJkrQzfSUk--fRwH1R3YkXxqrd7n4WiIKHeK0riX9CTB6Zg4lSSQf4=w1200|https://lh3.googleusercontent.com/pw/AP1GczOca9e-Z7erZR73ga76_rnzoHcFYlPXhbnNtzDWud0oPMdJEQoxj-KZ1o7LlaFHJtX4jQL1H4FTwy3GQ_ChvdsARR-cpDTPLxbRmvgzO0ck-r1oJb77=w1200|https://lh3.googleusercontent.com/pw/AP1GczOoqcTA7Elg-8HYseVZ5V2z8FMJ4jv4UhV9Kh7Ci_8fQNlDCnD3DpKVF2nmexRq1lqCaSrJkJxNgSfVKzf1Bucpve-cWbDySSUhYCVSgXgcRi2gk4ou=w1200|https://lh3.googleusercontent.com/pw/AP1GczOZyikEqhxenI-O0LmST7RMv_Wzw4g41Vf5Xpktl2zuGpyD_YpZGKfTqn3C63J1zL9oehpYgCQmc_Ry_iEhY1TYqofw6tha2EjndNFtaNSyJM4wjYWp=w1200|https://lh3.googleusercontent.com/pw/AP1GczO36Zy1EHB-O1SvGcI50nz6BYJ70mVZ00hDk2Qm1dosPu4cOdzucLOPq1vtwwgBUcwKLDSb4OBAz-3xsYfZx1wllPxof0lehos40gM-ehM3SdfaVzeT=w1200|https://lh3.googleusercontent.com/pw/AP1GczNtKyAm_fQx_WJhVw-kMk1_q5912KxhSiW6pQfmyWh7HInIURo0aWuFhabc8cMEVoCuORI3gaaL9aPAT6zWcNCsTeKoLq0TNIyeAJHd__Q0yDSG7Kg3=w1200
A4: =IFERROR(__xludf.DUMMYFUNCTION("""COMPUTED_VALUE"""),"2025") -> 2025 | B4: =IFERROR(__xludf.DUMMYFUNCTION("""COMPUTED_VALUE"""),"Casa en barrio Los Cámbulos II") -> Casa en barrio Los Cámbulos II | C4: =IFERROR(__xludf.DUMMYFUNCTION("""COMPUTED_VALUE"""),"Casa") -> Casa | D4: =IFERROR(__xludf.DUMMYFUNCTION("""COMPUTED_VALUE"""),"Los Cámbulos II") -> Los Cámbulos II | E4: =IFERROR(__xludf.DUMMYFUNCTION("""COMPUTED_VALUE""")," ") | F4: =IFERROR(__xludf.DUMMYFUNCTION("""COMPUTED_VALUE"""),3.0E8) -> 300000000 | G4: =IFERROR(__xludf.DUMMYFUNCTION("""COMPUTED_VALUE"""),"$300'000.000 a $400'000.000") -> $300'000.000 a $400'000.000 | J4: =IFERROR(__xludf.DUMMYFUNCTION("""COMPUTED_VALUE"""),"Norte") -> Norte | K4: =IFERROR(__xludf.DUMMYFUNCTION("""COMPUTED_VALUE"""),"2") -> 2 | L4: =IFERROR(__xludf.DUMMYFUNCTION("""COMPUTED_VALUE"""),6.0) -> 6 | N4: =IFERROR(__xludf.DUMMYFUNCTION("""COMPUTED_VALUE"""),2.0) -> 2 | O4: =IFERROR(__xludf.DUMMYFUNCTION("""COMPUTED_VALUE"""),1.0) -> 1 | P4: =IFERROR(__xludf.DUMMYFUNCTION("""COMPUTED_VALUE"""),2.0) -> 2 | Q4: =IFERROR(__xludf.DUMMYFUNCTION("""COMPUTED_VALUE"""),140.0) -> 140 | R4: =IFERROR(__xludf.DUMMYFUNCTION("""COMPUTED_VALUE"""),90.0) -> 90 | S4: =IFERROR(__xludf.DUMMYFUNCTION("""COMPUTED_VALUE""")," ") | T4: =IFERROR(__xludf.DUMMYFUNCTION("""COMPUTED_VALUE"""),"Neiva") -> Neiva | U4: =IFERROR(__xludf.DUMMYFUNCTION("""COMPUTED_VALUE"""),"3") -> 3 | V4: =IFERROR(__xludf.DUMMYFUNCTION("""COMPUTED_VALUE"""),"Medianera") -> Medianera | X4: =IFERROR(__xludf.DUMMYFUNCTION("""COMPUTED_VALUE"""),4.0) -> 4 | Y4: =IFERROR(__xludf.DUMMYFUNCTION("""COMPUTED_VALUE"""),"No tiene") -> No tiene | Z4: =IFERROR(__xludf.DUMMYFUNCTION("""COMPUTED_VALUE"""),"No aplica") -> No aplica | AA4: =IFERROR(__xludf.DUMMYFUNCTION("""COMPUTED_VALUE"""),"No aplica") -> No aplica | AB4: =IFERROR(__xludf.DUMMYFUNCTION("""COMPUTED_VALUE"""),"https://photos.app.goo.gl/5fGWK8Q6FdVAQXw98") -> https://photos.app.goo.gl/5fGWK8Q6FdVAQXw98 | AF4: =IFERROR(__xludf.DUMMYFUNCTION("""COMPUTED_VALUE"""),"semi-integral") -> semi-integral | AH4: =IFERROR(__xludf.DUMMYFUNCTION("""COMPUTED_VALUE"""),"Inventario") -> Inventario | AJ4: =IFERROR(__xludf.DUMMYFUNCTION("""COMPUTED_VALUE"""),"B-Inventario Los Cambulos II") -> B-Inventario Los Cambulos II | AL4: =IFERROR(__xludf.DUMMYFUNCTION("""COMPUTED_VALUE"""),"TIENE FOTOS") -> TIENE FOTOS | AM4: =IFERROR(__xludf.DUMMYFUNCTION("""COMPUTED_VALUE"""),3.212323681E9) -> 3212323681 | AN4: =IFERROR(__xludf.DUMMYFUNCTION("""COMPUTED_VALUE"""),3.135781638E9) -> 3135781638 | AP4: =IFERROR(__xludf.DUMMYFUNCTION("""COMPUTED_VALUE"""),"Carrera 12 # 33-24") -> Carrera 12 # 33-24 | AS4: =IFERROR(__xludf.DUMMYFUNCTION("""COMPUTED_VALUE"""),0.0) -> 0 | AT4: =IFERROR(__xludf.DUMMYFUNCTION("""COMPUTED_VALUE"""),0.0) -> 0 | AU4: =IFERROR(__xludf.DUMMYFUNCTION("""COMPUTED_VALUE"""),0.0) -> 0 | AV4: =IFERROR(__xludf.DUMMYFUNCTION("""COMPUTED_VALUE"""),0.0) -> 0 | AW4: =IFERROR(__xludf.DUMMYFUNCTION("""COMPUTED_VALUE"""),"NO") -> NO | AX4: =IFERROR(__xludf.DUMMYFUNCTION("""COMPUTED_VALUE"""),0.0) -> 0 | AY4: =IFERROR(__xludf.DUMMYFUNCTION("""COMPUTED_VALUE"""),0.0) -> 0 | AZ4: =IFERROR(__xludf.DUMMYFUNCTION("""COMPUTED_VALUE"""),6.0) -> 6 | BA4: =IFERROR(__xludf.DUMMYFUNCTION("""COMPUTED_VALUE"""),"X") -> X | BB4: =IFERROR(__xludf.DUMMYFUNCTION("""COMPUTED_VALUE"""),15.0) -> 15 | BC4: =IFERROR(__xludf.DUMMYFUNCTION("""COMPUTED_VALUE"""),"8 - ERNESTO POLANCO, 9 - ALBEIRO TOVAR") -> 8 - ERNESTO POLANCO, 9 - ALBEIRO TOVAR | BF4: =IFERROR(__xludf.DUMMYFUNCTION("""COMPUTED_VALUE"""),"https://lh3.googleusercontent.com/pw/AP1GczNiJ2WTMAT7mE7Vvqt81Bwzfk6FVv9tlijaYncZFHZYNHmwlHmb5HXAzBgCtiBLWoRNqJLrfBEAGtGC5CpQFJTxOfggFexN_mCIasqxrTumVvFn6gPO=w1200|https://lh3.googleusercontent.com/pw/AP1GczMoTaZSPGlIilMcMBR67uSopPBxjCVXWyrNfJ2--8roH3txtT"&"JZQLSBIPlidqR7L4cDRF69OI89VoToWoXpVvffIk-DhecGj-mZixgy0Qwb4S3dhh1D=w1200|https://lh3.googleusercontent.com/pw/AP1GczP7pR3aj8il8QzAyxGiKlwebH9w-cayYMlvB3CKBP3vJnrQy_CgbNdidTV0LYzhjVREtP8irAiGobXSUclt164Z_0kKlNRl1p7TlMnq034jTpBKAnap=w1200|https://lh3.google"&"usercontent.com/pw/AP1GczOqBG6RMa4UmToalEBdiGVEyxiwpHAuyHtdwLgrEGvB5E6BL7I0IqP18Fp87H4qYLGZxmOo0_o0Nk5IwL7hp_saiI5U18J40W6rjHwL2AesEyvZK7Pf=w1200|https://lh3.googleusercontent.com/pw/AP1GczOYDpophPphjZ_XOQhxrYdkgb1ULcEIo2OaCHdNR2ja_w3FXvygiKZTc-s107TLIl-F"&"K7lcRSZGcxyQMKomdtXnd1iRl7vzAXE2p1cQq5GdcKNxtVOm=w1200|https://lh3.googleusercontent.com/pw/AP1GczN5Ax_pur40sKfULmPIO7IotMe4ysxNGMl942q6T8L55tiKlvjj3z94nQ2EPqZ0nyUnWZzJ_fZq36Z7Rve1TNFlwJ0ynwKaeoYJMKNv7SDSGvk1R1Wq=w1200|https://lh3.googleusercontent.com/pw"&"/AP1GczP6kkquiOYs0oBn1zyKCk2AZ6IozTPgv-ZtNd1gPGExaIYdTa3jo0bc9kbivnRVMow7dL_ihev3bKLPJp4tTj7ZEDSnT-XcRmMN6MyOEgkzoZ5wKL7E=w1200|https://lh3.googleusercontent.com/pw/AP1GczNynOzf5U7dTYuEug5wKhTQ08OEBkiRlSnf4SJVZ5dBY5FJ6xeUoo_Ncnz1l8uoaGBD5tkmvgxV_PC737V-h1"&"7Fv5Q8Y9XwkL_cTF1nKTIHsnddv5x9=w1200|https://lh3.googleusercontent.com/pw/AP1GczMLtgappbFoKeYzn32a4bXk3Q-EzbxqCWEkY1XLAuqjb-u6VfVHNQwuME3L46WAsqf0zHOEhalZjDAE5FcJomOmxJMOH3lFwgA1L6E2U99dfbHOtcSm=w1200|https://lh3.googleusercontent.com/pw/AP1GczOxVjiI4IvHA"&"4wmH4gcvCwiD5lEoueyDdP7soOxQnkaA02sBO99ADzKeqYdmC8kuIpElz_sfyBP2GTdtj9Wm_reHcfaDi7UXFg3vR_M8CisAdELXZbE=w1200|https://lh3.googleusercontent.com/pw/AP1GczMAhyIiYQFKsssrY5sCRY9yGsiNR5zLP6G2VV2uveNq4LgVpZgUKmXkkEauKlyj2xkRvRQp3FYGdTVdontozmAR0T_ciaM4HgIaB8wS"&"yEsRG7A7O_G1=w1200|https://lh3.googleusercontent.com/pw/AP1GczP5ki9OojRO8-ZCn-HvC-AAM513WY_A9l8U9rT8eJM0jLDVxTuNJbuw8zSTeVOvTA5sGdA2O34nSrPWk_5rjz5f-WBjDEyMsRb6bh2CLFYdNqdB4V-5=w1200|https://lh3.googleusercontent.com/pw/AP1GczOImcZyGYskcTR-9D3SdTr1vmFfm0D"&"lzRZUakOKhcb8fph7N0u4j-X_HvEm0Cdwn-G0DENWLFAAEal8yPXyFJGmwmgRkP-xfV9b_-4EISuSXxXGchTV=w1200|https://lh3.googleusercontent.com/pw/AP1GczMWQJonWZufNMfmyRCFTMG9zKakEwaJe31q1jCqgj7Kbi-k4qERsgdl7FYEukrqJe9HKyBbnN5JT4azbr-xnIoWo4tWD4m9Lwlk8HZG_XcZRzZOzEn_=w1200"&"|https://lh3.googleusercontent.com/pw/AP1GczMxEUS1DQcCvPN4UOpcOv3PGoJmq8X5dGCd1gm07Pv7XpGYfqiOSdGG2mKWt4OWooa5yorM0v4C727CizzcTv7nELMampFm-uv7IJsTp5OpKxCNtUy9=w1200") -> https://lh3.googleusercontent.com/pw/AP1GczNiJ2WTMAT7mE7Vvqt81Bwzfk6FVv9tlijaYncZFHZYNHmwlHmb5HXAzBgCtiBLWoRNqJLrfBEAGtGC5CpQFJTxOfggFexN_mCIasqxrTumVvFn6gPO=w1200|https://lh3.googleusercontent.com/pw/AP1GczMoTaZSPGlIilMcMBR67uSopPBxjCVXWyrNfJ2--8roH3txtTJZQLSBIPlidqR7L4cDRF69OI89VoToWoXpVvffIk-DhecGj-mZixgy0Qwb4S3dhh1D=w1200|https://lh3.googleusercontent.com/pw/AP1GczP7pR3aj8il8QzAyxGiKlwebH9w-cayYMlvB3CKBP3vJnrQy_CgbNdidTV0LYzhjVREtP8irAiGobXSUclt164Z_0kKlNRl1p7TlMnq034jTpBKAnap=w1200|https://lh3.googleusercontent.com/pw/AP1GczOqBG6RMa4UmToalEBdiGVEyxiwpHAuyHtdwLgrEGvB5E6BL7I0IqP18Fp87H4qYLGZxmOo0_o0Nk5IwL7hp_saiI5U18J40W6rjHwL2AesEyvZK7Pf=w1200|https://lh3.googleusercontent.com/pw/AP1GczOYDpophPphjZ_XOQhxrYdkgb1ULcEIo2OaCHdNR2ja_w3FXvygiKZTc-s107TLIl-FK7lcRSZGcxyQMKomdtXnd1iRl7vzAXE2p1cQq5GdcKNxtVOm=w1200|https://lh3.googleusercontent.com/pw/AP1GczN5Ax_pur40sKfULmPIO7IotMe4ysxNGMl942q6T8L55tiKlvjj3z94nQ2EPqZ0nyUnWZzJ_fZq36Z7Rve1TNFlwJ0ynwKaeoYJMKNv7SDSGvk1R1Wq=w1200|https://lh3.googleusercontent.com/pw/AP1GczP6kkquiOYs0oBn1zyKCk2AZ6IozTPgv-ZtNd1gPGExaIYdTa3jo0bc9kbivnRVMow7dL_ihev3bKLPJp4tTj7ZEDSnT-XcRmMN6MyOEgkzoZ5wKL7E=w1200|https://lh3.googleusercontent.com/pw/AP1GczNynOzf5U7dTYuEug5wKhTQ08OEBkiRlSnf4SJVZ5dBY5FJ6xeUoo_Ncnz1l8uoaGBD5tkmvgxV_PC737V-h17Fv5Q8Y9XwkL_cTF1nKTIHsnddv5x9=w1200|https://lh3.googleusercontent.com/pw/AP1GczMLtgappbFoKeYzn32a4bXk3Q-EzbxqCWEkY1XLAuqjb-u6VfVHNQwuME3L46WAsqf0zHOEhalZjDAE5FcJomOmxJMOH3lFwgA1L6E2U99dfbHOtcSm=w1200|https://lh3.googleusercontent.com/pw/AP1GczOxVjiI4IvHA4wmH4gcvCwiD5lEoueyDdP7soOxQnkaA02sBO99ADzKeqYdmC8kuIpElz_sfyBP2GTdtj9Wm_reHcfaDi7UXFg3vR_M8CisAdELXZbE=w1200|https://lh3.googleusercontent.com/pw/AP1GczMAhyIiYQFKsssrY5sCRY9yGsiNR5zLP6G2VV2uveNq4LgVpZgUKmXkkEauKlyj2xkRvRQp3FYGdTVdontozmAR0T_ciaM4HgIaB8wSyEsRG7A7O_G1=w1200|https://lh3.googleusercontent.com/pw/AP1GczP5ki9OojRO8-ZCn-HvC-AAM513WY_A9l8U9rT8eJM0jLDVxTuNJbuw8zSTeVOvTA5sGdA2O34nSrPWk_5rjz5f-WBjDEyMsRb6bh2CLFYdNqdB4V-5=w1200|https://lh3.googleusercontent.com/pw/AP1GczOImcZyGYskcTR-9D3SdTr1vmFfm0DlzRZUakOKhcb8fph7N0u4j-X_HvEm0Cdwn-G0DENWLFAAEal8yPXyFJGmwmgRkP-xfV9b_-4EISuSXxXGchTV=w1200|https://lh3.googleusercontent.com/pw/AP1GczMWQJonWZufNMfmyRCFTMG9zKakEwaJe31q1jCqgj7Kbi-k4qERsgdl7FYEukrqJe9HKyBbnN5JT4azbr-xnIoWo4tWD4m9Lwlk8HZG_XcZRzZOzEn_=w1200|https://lh3.googleusercontent.com/pw/AP1GczMxEUS1DQcCvPN4UOpcOv3PGoJmq8X5dGCd1gm07Pv7XpGYfqiOSdGG2mKWt4OWooa5yorM0v4C727CizzcTv7nELMampFm-uv7IJsTp5OpKxCNtUy9=w1200
A5: =IFERROR(__xludf.DUMMYFUNCTION("""COMPUTED_VALUE"""),"3118") -> 3118 | B5: =IFERROR(__xludf.DUMMYFUNCTION("""COMPUTED_VALUE"""),"Casa en barrio Quirinal") -> Casa en barrio Quirinal | C5: =IFERROR(__xludf.DUMMYFUNCTION("""COMPUTED_VALUE"""),"Casa") -> Casa | D5: =IFERROR(__xludf.DUMMYFUNCTION("""COMPUTED_VALUE"""),"Quirinal") -> Quirinal | F5: =IFERROR(__xludf.DUMMYFUNCTION("""COMPUTED_VALUE"""),9.0E8) -> 900000000 | G5: =IFERROR(__xludf.DUMMYFUNCTION("""COMPUTED_VALUE"""),"$500'000.000 a $1.000'000.000") -> $500'000.000 a $1.000'000.000 | J5: =IFERROR(__xludf.DUMMYFUNCTION("""COMPUTED_VALUE"""),"Centro") -> Centro | K5: =IFERROR(__xludf.DUMMYFUNCTION("""COMPUTED_VALUE"""),"3") -> 3 | L5: =IFERROR(__xludf.DUMMYFUNCTION("""COMPUTED_VALUE"""),6.0) -> 6 | N5: =IFERROR(__xludf.DUMMYFUNCTION("""COMPUTED_VALUE"""),3.0) -> 3 | O5: =IFERROR(__xludf.DUMMYFUNCTION("""COMPUTED_VALUE"""),1.0) -> 1 | P5: =IFERROR(__xludf.DUMMYFUNCTION("""COMPUTED_VALUE"""),2.0) -> 2 | R5: =IFERROR(__xludf.DUMMYFUNCTION("""COMPUTED_VALUE"""),323.0) -> 323 | S5: =IFERROR(__xludf.DUMMYFUNCTION("""COMPUTED_VALUE""")," ") | T5: =IFERROR(__xludf.DUMMYFUNCTION("""COMPUTED_VALUE"""),"Neiva") -> Neiva | U5: =IFERROR(__xludf.DUMMYFUNCTION("""COMPUTED_VALUE"""),"4") -> 4 | V5: =IFERROR(__xludf.DUMMYFUNCTION("""COMPUTED_VALUE"""),"Esquinera") -> Esquinera | X5: =IFERROR(__xludf.DUMMYFUNCTION("""COMPUTED_VALUE"""),5.0) -> 5 | Y5: =IFERROR(__xludf.DUMMYFUNCTION("""COMPUTED_VALUE"""),"No tiene") -> No tiene | Z5: =IFERROR(__xludf.DUMMYFUNCTION("""COMPUTED_VALUE"""),"No aplica") -> No aplica | AA5: =IFERROR(__xludf.DUMMYFUNCTION("""COMPUTED_VALUE"""),"No aplica") -> No aplica | AB5: =IFERROR(__xludf.DUMMYFUNCTION("""COMPUTED_VALUE"""),"https://photos.app.goo.gl/JsmPogvXQAzJjipm7") -> https://photos.app.goo.gl/JsmPogvXQAzJjipm7 | AF5: =IFERROR(__xludf.DUMMYFUNCTION("""COMPUTED_VALUE"""),"semi-integral") -> semi-integral | AH5: =IFERROR(__xludf.DUMMYFUNCTION("""COMPUTED_VALUE"""),"Inventario") -> Inventario | AJ5: =IFERROR(__xludf.DUMMYFUNCTION("""COMPUTED_VALUE"""),"B-Inventario Quirinal") -> B-Inventario Quirinal | AL5: =IFERROR(__xludf.DUMMYFUNCTION("""COMPUTED_VALUE"""),"TIENE FOTOS") -> TIENE FOTOS | AM5: =IFERROR(__xludf.DUMMYFUNCTION("""COMPUTED_VALUE"""),3.212323681E9) -> 3212323681 | AN5: =IFERROR(__xludf.DUMMYFUNCTION("""COMPUTED_VALUE"""),3.135781638E9) -> 3135781638 | AP5: =IFERROR(__xludf.DUMMYFUNCTION("""COMPUTED_VALUE"""),"Calle 17 A No. 7-73") -> Calle 17 A No. 7-73 | AS5: =IFERROR(__xludf.DUMMYFUNCTION("""COMPUTED_VALUE"""),0.0) -> 0 | AT5: =IFERROR(__xludf.DUMMYFUNCTION("""COMPUTED_VALUE"""),0.0) -> 0 | AU5: =IFERROR(__xludf.DUMMYFUNCTION("""COMPUTED_VALUE"""),0.0) -> 0 | AV5: =IFERROR(__xludf.DUMMYFUNCTION("""COMPUTED_VALUE"""),0.0) -> 0 | AW5: =IFERROR(__xludf.DUMMYFUNCTION("""COMPUTED_VALUE"""),"NO") -> NO | AX5: =IFERROR(__xludf.DUMMYFUNCTION("""COMPUTED_VALUE"""),0.0) -> 0 | AY5: =IFERROR(__xludf.DUMMYFUNCTION("""COMPUTED_VALUE"""),0.0) -> 0 | AZ5: =IFERROR(__xludf.DUMMYFUNCTION("""COMPUTED_VALUE"""),0.0) -> 0 | BA5: =IFERROR(__xludf.DUMMYFUNCTION("""COMPUTED_VALUE"""),"X") -> X | BB5: =IFERROR(__xludf.DUMMYFUNCTION("""COMPUTED_VALUE"""),0.0) -> 0 | BC5: =IFERROR(__xludf.DUMMYFUNCTION("""COMPUTED_VALUE"""),"2 - JAIRO DIAZ, 39 - JHONATHA, 39 - JHONATHAN") -> 2 - JAIRO DIAZ, 39 - JHONATHA, 39 - JHONATHAN | BF5: =IFERROR(__xludf.DUMMYFUNCTION("""COMPUTED_VALUE"""),"https://lh3.googleusercontent.com/pw/AP1GczNg2rwgsskmo-_A3mKJ-dyYpYRdYtkQTk_wN_XnpGymgQBxUvht_vICWWXt5UdWMjuQf089l5hSPaLJw0x0PLnhTLcugkJJUgjCvm6zL-pt7Ex8VE2z=w1200|https://lh3.googleusercontent.com/pw/AP1GczOzH2Pj3Qg3vdO1_DqlyU6j1VC7Z8J4heGwAq5ohoRcXo8eCS"&"QTguDEAL6tq9VT2Kzpdt5WTXqKiZXluRo1GCnDxhslObSfp17ab9b80MynXhPu9FGS=w1200|https://lh3.googleusercontent.com/pw/AP1GczM0reGmmBkst7N_xJ6UETL55bBv5GtzYYrqWQ8OzB48W2vwY7UQHJbSDo9K-c3NOQypz962fqvljXmChjvafe1sK8fHtIHgke5Z5dYn7kwgKe_nIhY2=w1200|https://lh3.google"&"usercontent.com/pw/AP1GczMq93394K4U1GY9tfsZiz01XOoVyDCQunpS2IZu1tr2M_pEZLNUJL_vcBIuRqyXwBfl7etkAv5tJOoQkngw6JjDm46dzh6kuHvvJmkQwgSdnyg2ouwD=w1200|https://lh3.googleusercontent.com/pw/AP1GczM-tCnQduwmrt9kPzVxV8UnBeNOd-XLv_4pXGe2HXihFVwZaYm0HxPXaHEmXgW885ZI"&"7_JIDZgMbFjg6_SYBKgcSXfFKOO_gELQx_nWmlRp1Lf4nDvY=w1200|https://lh3.googleusercontent.com/pw/AP1GczPIuI7Vg7XAU6QAP_obauw49fTpvXND8CuOW9x12PYKkWd2ubiV0M0TiYJhzGn0lCt38dXziLC2f3TJoOxh-4f_oGlUKKMLI6lEd7VyQ-2Eni9we0bw=w1200|https://lh3.googleusercontent.com/pw"&"/AP1GczOAmjmjTHnEt12WNlc0w5BT1YvvpVW4QEfmxNMR8slJN2_D529fJFlxRelfKp4F0fY1jpLx50va0x-Sr32YWizLkaHDROF2A3HtvtTPKMi5d8pG8AXA=w1200|https://lh3.googleusercontent.com/pw/AP1GczOZhd_dKfATMRSVw9mLTSf2MNcZzGkiP3gWtJoi8cWyDuZGs6GDUUA66FvmJ49DInR2DdSFfpITvR_By0w1R0"&"ESzkfqAGPgmIy6RntcY8ZI-i0sDCMv=w1200|https://lh3.googleusercontent.com/pw/AP1GczNmlOHjHOOz_8v1eLcUkxJuAVX3iCWw__VfQE8kbzH7UVUm4KEj66cPSb3RDuwe9Xho8EVkyy51DjcZmz7AFcEBsrckJS3unQ9g1sh8Nrp1pvCoUckS=w1200|https://lh3.googleusercontent.com/pw/AP1GczO5gbayHS-EB"&"fX0mE1adstUpQ_ZIROAG6dlPuGoafBSwzpV9L2JwyH6NjHvIivYgKvqnGpVie9b8zth_5PVzHNdtN3CcYX8XkKqCLImbplETybZGjH4=w1200|https://lh3.googleusercontent.com/pw/AP1GczNLrUp3o3JgaWjBtOWz7_eHixafJuv0xDgp5YYDl28_fil2piaUnjEbJuRMylo83PEQl4CbISGlR6liWGMlNp8oyVVm41-LABgCIAEp"&"uqGYboqPxIOM=w1200|https://lh3.googleusercontent.com/pw/AP1GczNpemxJ7zfjZ4pgnwcfK7ZMHyiS8meImxAS_BWPLziHSKytwflVsx9RqDNmezJygSe_wdne82pLDMy_EPFKP6a_Kph9ty7WAvIGo1kFxpIY6y_XT2QY=w1200|https://lh3.googleusercontent.com/pw/AP1GczNAmJ35ntXvSBHuCyAYvc_8U7qZDxz"&"pE4UcLlEyLdhOkm7-xo_1jTmmR6bFT595yHqtD2fvIu4X2tnaA-C9e1mEJstr4gZ485EXcRo6KsCm9yE-giiC=w1200|https://lh3.googleusercontent.com/pw/AP1GczMhco40CNWULWuDdBoNOJgoziHx0H3rmUDAx1fh0f7CjvTLCt-RiA4UFkcjvoFMDlXCZYB2UPWJ6Y93oAmEKbS0lwY4HfrfH6lb_BpbaVlcAaTRMrmy=w1200"&"|https://lh3.googleusercontent.com/pw/AP1GczNhiDKbPW9zrX1-A2OFKsTq6NhgrPZIDC5qHcysEh90srBZ-hiaHfN2PWAEACcZvlDqXBrELC4pl_9UJ04bzcXlOqHzfLO10R1H5tu4qSfiJSlcyTU8=w1200|https://lh3.googleusercontent.com/pw/AP1GczPH1PC7MoAB9ZlO2YZ5QlrKv8GheVVa1UX_Dr8Dkb0TEczdb"&"MA0fIImqc0TS3hloDRjJWG0mYuTKGy7-i6B2_lT6ag3-cMLc6odgFRGNamTICegg_-Y=w1200|https://lh3.googleusercontent.com/pw/AP1GczPp-h9J0CIzgLW7_6Hlao-NIwJBol5_YGJRQqbZRn3TUxgW5t-nJByW3dnaIJEyGOMOguGsTOGRzFFtk50nBUxjwx0J4ypSMJCsqwG9rNjzRXM0m2Bx=w1200|https://lh3.googl"&"eusercontent.com/pw/AP1GczMXiMMdrkJ1QmsHO_pfZxQkqMgn7KKIffOB6MhyR79KPG4hpEIj77jx3gEqs-Qpi06lCp3GXqFdzThJrSRrSZ4Flvt6YS8Tp87ClXNV0_ctym68OzzV=w1200|https://lh3.googleusercontent.com/pw/AP1GczPx1RrMeOhIr10rahDjBDrF8G5wnRmmDLSW-BqOcyVzQZZcNiVo8McZ_vE6dgCOTiX"&"bdWHAACO9QsvMCn_8mm5TWXQzFwMOYbHqThCAWrAzLUTCLFWc=w1200|https://lh3.googleusercontent.com/pw/AP1GczOGrMzCO3VX-5JY_voaWemeaIk1rNsqOD3iCaf82W8ypS4eZdOhWPkQtDoC3jhHgJhXd_2n64UJvSXXttFDx9zIqkp7XTve9fdK0muB0yOpuHOO-6z1=w1200|https://lh3.googleusercontent.com/p"&"w/AP1GczOGJ4n9H0Kwu7kBXj3F20-Mzlh3Qmh1YNEMWUjEzLzZygE5n9mVFVughUEOlaiv2yTHAvvlfPN4M4bX9KQkSexvla7BazpE8uxboE-XCPiYYx9liNT4=w1200") -> https://lh3.googleusercontent.com/pw/AP1GczNg2rwgsskmo-_A3mKJ-dyYpYRdYtkQTk_wN_XnpGymgQBxUvht_vICWWXt5UdWMjuQf089l5hSPaLJw0x0PLnhTLcugkJJUgjCvm6zL-pt7Ex8VE2z=w1200|https://lh3.googleusercontent.com/pw/AP1GczOzH2Pj3Qg3vdO1_DqlyU6j1VC7Z8J4heGwAq5ohoRcXo8eCSQTguDEAL6tq9VT2Kzpdt5WTXqKiZXluRo1GCnDxhslObSfp17ab9b80MynXhPu9FGS=w1200|https://lh3.googleusercontent.com/pw/AP1GczM0reGmmBkst7N_xJ6UETL55bBv5GtzYYrqWQ8OzB48W2vwY7UQHJbSDo9K-c3NOQypz962fqvljXmChjvafe1sK8fHtIHgke5Z5dYn7kwgKe_nIhY2=w1200|https://lh3.googleusercontent.com/pw/AP1GczMq93394K4U1GY9tfsZiz01XOoVyDCQunpS2IZu1tr2M_pEZLNUJL_vcBIuRqyXwBfl7etkAv5tJOoQkngw6JjDm46dzh6kuHvvJmkQwgSdnyg2ouwD=w1200|https://lh3.googleusercontent.com/pw/AP1GczM-tCnQduwmrt9kPzVxV8UnBeNOd-XLv_4pXGe2HXihFVwZaYm0HxPXaHEmXgW885ZI7_JIDZgMbFjg6_SYBKgcSXfFKOO_gELQx_nWmlRp1Lf4nDvY=w1200|https://lh3.googleusercontent.com/pw/AP1GczPIuI7Vg7XAU6QAP_obauw49fTpvXND8CuOW9x12PYKkWd2ubiV0M0TiYJhzGn0lCt38dXziLC2f3TJoOxh-4f_oGlUKKMLI6lEd7VyQ-2Eni9we0bw=w1200|https://lh3.googleusercontent.com/pw/AP1GczOAmjmjTHnEt12WNlc0w5BT1YvvpVW4QEfmxNMR8slJN2_D529fJFlxRelfKp4F0fY1jpLx50va0x-Sr32YWizLkaHDROF2A3HtvtTPKMi5d8pG8AXA=w1200|https://lh3.googleusercontent.com/pw/AP1GczOZhd_dKfATMRSVw9mLTSf2MNcZzGkiP3gWtJoi8cWyDuZGs6GDUUA66FvmJ49DInR2DdSFfpITvR_By0w1R0ESzkfqAGPgmIy6RntcY8ZI-i0sDCMv=w1200|https://lh3.googleusercontent.com/pw/AP1GczNmlOHjHOOz_8v1eLcUkxJuAVX3iCWw__VfQE8kbzH7UVUm4KEj66cPSb3RDuwe9Xho8EVkyy51DjcZmz7AFcEBsrckJS3unQ9g1sh8Nrp1pvCoUckS=w1200|https://lh3.googleusercontent.com/pw/AP1GczO5gbayHS-EBfX0mE1adstUpQ_ZIROAG6dlPuGoafBSwzpV9L2JwyH6NjHvIivYgKvqnGpVie9b8zth_5PVzHNdtN3CcYX8XkKqCLImbplETybZGjH4=w1200|https://lh3.googleusercontent.com/pw/AP1GczNLrUp3o3JgaWjBtOWz7_eHixafJuv0xDgp5YYDl28_fil2piaUnjEbJuRMylo83PEQl4CbISGlR6liWGMlNp8oyVVm41-LABgCIAEpuqGYboqPxIOM=w1200|https://lh3.googleusercontent.com/pw/AP1GczNpemxJ7zfjZ4pgnwcfK7ZMHyiS8meImxAS_BWPLziHSKytwflVsx9RqDNmezJygSe_wdne82pLDMy_EPFKP6a_Kph9ty7WAvIGo1kFxpIY6y_XT2QY=w1200|https://lh3.googleusercontent.com/pw/AP1GczNAmJ35ntXvSBHuCyAYvc_8U7qZDxzpE4UcLlEyLdhOkm7-xo_1jTmmR6bFT595yHqtD2fvIu4X2tnaA-C9e1mEJstr4gZ485EXcRo6KsCm9yE-giiC=w1200|https://lh3.googleusercontent.com/pw/AP1GczMhco40CNWULWuDdBoNOJgoziHx0H3rmUDAx1fh0f7CjvTLCt-RiA4UFkcjvoFMDlXCZYB2UPWJ6Y93oAmEKbS0lwY4HfrfH6lb_BpbaVlcAaTRMrmy=w1200|https://lh3.googleusercontent.com/pw/AP1GczNhiDKbPW9zrX1-A2OFKsTq6NhgrPZIDC5qHcysEh90srBZ-hiaHfN2PWAEACcZvlDqXBrELC4pl_9UJ04bzcXlOqHzfLO10R1H5tu4qSfiJSlcyTU8=w1200|https://lh3.googleusercontent.com/pw/AP1GczPH1PC7MoAB9ZlO2YZ5QlrKv8GheVVa1UX_Dr8Dkb0TEczdbMA0fIImqc0TS3hloDRjJWG0mYuTKGy7-i6B2_lT6ag3-cMLc6odgFRGNamTICegg_-Y=w1200|https://lh3.googleusercontent.com/pw/AP1GczPp-h9J0CIzgLW7_6Hlao-NIwJBol5_YGJRQqbZRn3TUxgW5t-nJByW3dnaIJEyGOMOguGsTOGRzFFtk50nBUxjwx0J4ypSMJCsqwG9rNjzRXM0m2Bx=w1200|https://lh3.googleusercontent.com/pw/AP1GczMXiMMdrkJ1QmsHO_pfZxQkqMgn7KKIffOB6MhyR79KPG4hpEIj77jx3gEqs-Qpi06lCp3GXqFdzThJrSRrSZ4Flvt6YS8Tp87ClXNV0_ctym68OzzV=w1200|https://lh3.googleusercontent.com/pw/AP1GczPx1RrMeOhIr10rahDjBDrF8G5wnRmmDLSW-BqOcyVzQZZcNiVo8McZ_vE6dgCOTiXbdWHAACO9QsvMCn_8mm5TWXQzFwMOYbHqThCAWrAzLUTCLFWc=w1200|https://lh3.googleusercontent.com/pw/AP1GczOGrMzCO3VX-5JY_voaWemeaIk1rNsqOD3iCaf82W8ypS4eZdOhWPkQtDoC3jhHgJhXd_2n64UJvSXXttFDx9zIqkp7XTve9fdK0muB0yOpuHOO-6z1=w1200|https://lh3.googleusercontent.com/pw/AP1GczOGJ4n9H0Kwu7kBXj3F20-Mzlh3Qmh1YNEMWUjEzLzZygE5n9mVFVughUEOlaiv2yTHAvvlfPN4M4bX9KQkSexvla7BazpE8uxboE-XCPiYYx9liNT4=w1200
A6: =IFERROR(__xludf.DUMMYFUNCTION("""COMPUTED_VALUE"""),"2843") -> 2843 | B6: =IFERROR(__xludf.DUMMYFUNCTION("""COMPUTED_VALUE"""),"Casa en barrio Sevilla") -> Casa en barrio Sevilla | C6: =IFERROR(__xludf.DUMMYFUNCTION("""COMPUTED_VALUE"""),"Casa") -> Casa | D6: =IFERROR(__xludf.DUMMYFUNCTION("""COMPUTED_VALUE"""),"Sevilla") -> Sevilla | F6: =IFERROR(__xludf.DUMMYFUNCTION("""COMPUTED_VALUE"""),7.0E8) -> 700000000 | G6: =IFERROR(__xludf.DUMMYFUNCTION("""COMPUTED_VALUE"""),"$500'000.000 a $1.000'000.000") -> $500'000.000 a $1.000'000.000 | J6: =IFERROR(__xludf.DUMMYFUNCTION("""COMPUTED_VALUE"""),"Centro") -> Centro | K6: =IFERROR(__xludf.DUMMYFUNCTION("""COMPUTED_VALUE"""),"3") -> 3 | L6: =IFERROR(__xludf.DUMMYFUNCTION("""COMPUTED_VALUE"""),3.0) -> 3 | N6: =IFERROR(__xludf.DUMMYFUNCTION("""COMPUTED_VALUE"""),6.0) -> 6 | O6: =IFERROR(__xludf.DUMMYFUNCTION("""COMPUTED_VALUE"""),1.0) -> 1 | P6: =IFERROR(__xludf.DUMMYFUNCTION("""COMPUTED_VALUE"""),2.0) -> 2 | R6: =IFERROR(__xludf.DUMMYFUNCTION("""COMPUTED_VALUE"""),364.0) -> 364 | S6: =IFERROR(__xludf.DUMMYFUNCTION("""COMPUTED_VALUE""")," ") | T6: =IFERROR(__xludf.DUMMYFUNCTION("""COMPUTED_VALUE"""),"Neiva") -> Neiva | U6: =IFERROR(__xludf.DUMMYFUNCTION("""COMPUTED_VALUE"""),"4") -> 4 | V6: =IFERROR(__xludf.DUMMYFUNCTION("""COMPUTED_VALUE"""),"Medianera") -> Medianera | X6: =IFERROR(__xludf.DUMMYFUNCTION("""COMPUTED_VALUE"""),3.0) -> 3 | Y6: =IFERROR(__xludf.DUMMYFUNCTION("""COMPUTED_VALUE"""),"No tiene") -> No tiene | Z6: =IFERROR(__xludf.DUMMYFUNCTION("""COMPUTED_VALUE"""),"No aplica") -> No aplica | AA6: =IFERROR(__xludf.DUMMYFUNCTION("""COMPUTED_VALUE"""),"No aplica") -> No aplica | AB6: =IFERROR(__xludf.DUMMYFUNCTION("""COMPUTED_VALUE"""),"https://photos.app.goo.gl/MFdMkcBc3i82eZUV7") -> https://photos.app.goo.gl/MFdMkcBc3i82eZUV7 | AF6: =IFERROR(__xludf.DUMMYFUNCTION("""COMPUTED_VALUE"""),"integral") -> integral | AH6: =IFERROR(__xludf.DUMMYFUNCTION("""COMPUTED_VALUE"""),"Inventario") -> Inventario | AJ6: =IFERROR(__xludf.DUMMYFUNCTION("""COMPUTED_VALUE"""),"B-Inventario Sevilla") -> B-Inventario Sevilla | AL6: =IFERROR(__xludf.DUMMYFUNCTION("""COMPUTED_VALUE"""),"TIENE FOTOS") -> TIENE FOTOS | AM6: =IFERROR(__xludf.DUMMYFUNCTION("""COMPUTED_VALUE"""),3.212323681E9) -> 3212323681 | AN6: =IFERROR(__xludf.DUMMYFUNCTION("""COMPUTED_VALUE"""),3.135781638E9) -> 3135781638 | AP6: =IFERROR(__xludf.DUMMYFUNCTION("""COMPUTED_VALUE"""),"CARRERA 5 B NO. 21-31") -> CARRERA 5 B NO. 21-31 | AS6: =IFERROR(__xludf.DUMMYFUNCTION("""COMPUTED_VALUE"""),0.0) -> 0 | AT6: =IFERROR(__xludf.DUMMYFUNCTION("""COMPUTED_VALUE"""),0.0) -> 0 | AU6: =IFERROR(__xludf.DUMMYFUNCTION("""COMPUTED_VALUE"""),0.0) -> 0 | AV6: =IFERROR(__xludf.DUMMYFUNCTION("""COMPUTED_VALUE"""),0.0) -> 0 | AW6: =IFERROR(__xludf.DUMMYFUNCTION("""COMPUTED_VALUE"""),"NO") -> NO | AX6: =IFERROR(__xludf.DUMMYFUNCTION("""COMPUTED_VALUE"""),0.0) -> 0 | AY6: =IFERROR(__xludf.DUMMYFUNCTION("""COMPUTED_VALUE"""),0.0) -> 0 | AZ6: =IFERROR(__xludf.DUMMYFUNCTION("""COMPUTED_VALUE"""),0.0) -> 0 | BA6: =IFERROR(__xludf.DUMMYFUNCTION("""COMPUTED_VALUE"""),"X") -> X | BB6: =IFERROR(__xludf.DUMMYFUNCTION("""COMPUTED_VALUE"""),0.0) -> 0 | BF6: =IFERROR(__xludf.DUMMYFUNCTION("""COMPUTED_VALUE"""),"❌ Error: HTTP 404 para: https://photos.google.com/share/AF1QipPawSbNB9VDr7unrUk6mOMjTi-KhXmb-saTz_Kx8D0ns6KyZTpWeJutjM2WgS8-jQ?key=eWljS09zUVFacFoyRk1fYndRbDlPNHkyUDBWcjZB") -> ❌ Error: HTTP 404 para: https://photos.google.com/share/AF1QipPawSbNB9VDr7unrUk6mOMjTi-KhXmb-saTz_Kx8D0ns6KyZTpWeJutjM2WgS8-jQ?key=eWljS09zUVFacFoyRk1fYndRbDlPNHkyUDBWcjZB
